Workbook
Name Names: Chars!$A$2:$A$101

Sheet main
A1: Char | B1: Melee | C1: Agility | D1: Strength | E1: Stamina | F1: Intellect | G1: Instinct | H1: Psionic | I1: initiative | J1: HP | K1: average roll | AA1: =_xlfn.CONCAT($A$2," WINS!") -> Chester Wilkinson WINS! | AB1: =_xlfn.CONCAT($A$3," WINS!") -> Alexander Ashley WINS!
A2: Chester Wilkinson | B2: =SUMIFS(Chars!B$2:B$30,Chars!$A$2:$A$30,$A$2) -> 33 | C2: =SUMIFS(Chars!C$2:C$30,Chars!$A$2:$A$30,$A$2) -> 30 | D2: =SUMIFS(Chars!D$2:D$30,Chars!$A$2:$A$30,$A$2) -> 26 | E2: =SUMIFS(Chars!E$2:E$30,Chars!$A$2:$A$30,$A$2) -> 29 | F2: =SUMIFS(Chars!F$2:F$30,Chars!$A$2:$A$30,$A$2) -> 39 | G2: =SUMIFS(Chars!G$2:G$30,Chars!$A$2:$A$30,$A$2) -> 39 | H2: =SUMIFS(Chars!H$2:H$30,Chars!$A$2:$A$30,$A$2) -> 8 | I2: =B2+C2+F2+G2 -> 141 | J2: =K4*(B2+C2+D2+E2) -> 118 | K2: =calc!DA66 -> 47.533333 | AA2: =COUNTIF(calc!$DH$125:$DH$174,main!$AA$1) -> 0 | AB2: =COUNTIF(calc!$DH$125:$DH$174,main!$AB$1) -> 1
A3: Alexander Ashley | B3: =SUMIFS(Chars!B$2:B$30,Chars!$A$2:$A$30,$A$3) -> 8 | C3: =SUMIFS(Chars!C$2:C$30,Chars!$A$2:$A$30,$A$3) -> 25 | D3: =SUMIFS(Chars!D$2:D$30,Chars!$A$2:$A$30,$A$3) -> 21 | E3: =SUMIFS(Chars!E$2:E$30,Chars!$A$2:$A$30,$A$3) -> 27 | F3: =SUMIFS(Chars!F$2:F$30,Chars!$A$2:$A$30,$A$3) -> 14 | G3: =SUMIFS(Chars!G$2:G$30,Chars!$A$2:$A$30,$A$3) -> 6 | H3: =SUMIFS(Chars!H$2:H$30,Chars!$A$2:$A$30,$A$3) -> 12 | I3: =B3+C3+F3+G3 -> 53 | J3: =K4*(B3+C3+D3+E3) -> 81 | K3: =calc!DA67 -> 55 | AA3: =COUNTIF(calc2!$DH$125:$DH$174,main!$AA$1) -> 1 | AB3: =COUNTIF(calc2!$DH$125:$DH$174,main!$AB$1) -> 0
J4: HPkoef | K4: 1 | AA4: =COUNTIF(calc3!$DH$125:$DH$174,main!$AA$1) -> 1 | AB4: =COUNTIF(calc3!$DH$125:$DH$174,main!$AB$1) -> 0
C5: MISS | D5: DMGonly | E5: DMG+Effect | F5: DMG+Crit+ | G5: CritEff | H5: =_xlfn.CONCAT(A2," HP") -> Chester Wilkinson HP | I5: =_xlfn.CONCAT(A3," HP") -> Alexander Ashley HP | AA5: =COUNTIF(calc4!$DH$125:$DH$174,main!$AA$1) -> 1 | AB5: =COUNTIF(calc4!$DH$125:$DH$174,main!$AB$1) -> 0
A6: =IF(H6="","",calc!CY125) -> 1 turn | B6: =IF(H6="","",calc!CZ125) -> Chester Wilkinson | C6: =IF(H6="","",calc!DA125) -> miss | D6: =IF(H6="","",calc!DB125) -> 0 | E6: =IF(H6="","",calc!DC125) -> 0 | F6: =IF(H6="","",calc!DD125) -> 0 | G6: =IF(H6="","",calc!DE125) | H6: =IF(calc!DF125>0,calc!DF125,"") -> 118 | I6: =IF(calc!DG125>0,calc!DG125,"") -> 103 | J6: =calc!DH125 | L6: Double click the black cell below and then hit ENTER to reroll fight | AA6: =COUNTIF(calc5!$DH$125:$DH$174,main!$AA$1) -> 1 | AB6: =COUNTIF(calc5!$DH$125:$DH$174,main!$AB$1) -> 0
A7: =IF(H7="","",calc!CY126) -> 2 turn | B7: =IF(H7="","",calc!CZ126) -> Alexander Ashley | C7: =IF(H7="","",calc!DA126) -> - | D7: =IF(H7="","",calc!DB126) -> 21 | E7: =IF(H7="","",calc!DC126) -> 0 | F7: =IF(H7="","",calc!DD126) -> 0 | G7: =IF(H7="","",calc!DE126) | H7: =IF(calc!DF126>0,calc!DF126,"") -> 118 | I7: =IF(calc!DG126>0,calc!DG126,"") -> 103 | J7: =calc!DH126
A8: =IF(H8="","",calc!CY127) -> 3 turn | B8: =IF(H8="","",calc!CZ127) -> Chester Wilkinson | C8: =IF(H8="","",calc!DA127) -> - | D8: =IF(H8="","",calc!DB127) -> 26 | E8: =IF(H8="","",calc!DC127) -> 0 | F8: =IF(H8="","",calc!DD127) -> 0 | G8: =IF(H8="","",calc!DE127) | H8: =IF(calc!DF127>0,calc!DF127,"") -> 97 | I8: =IF(calc!DG127>0,calc!DG127,"") -> 103 | J8: =calc!DH127
A9: =IF(H9="","",calc!CY128) -> 4 turn | B9: =IF(H9="","",calc!CZ128) -> Alexander Ashley | C9: =IF(H9="","",calc!DA128) -> miss | D9: =IF(H9="","",calc!DB128) -> 0 | E9: =IF(H9="","",calc!DC128) -> 0 | F9: =IF(H9="","",calc!DD128) -> 0 | G9: =IF(H9="","",calc!DE128) | H9: =IF(calc!DF128>0,calc!DF128,"") -> 97 | I9: =IF(calc!DG128>0,calc!DG128,"") -> 77 | J9: =calc!DH128
A10: =IF(H10="","",calc!CY129) -> 5 turn | B10: =IF(H10="","",calc!CZ129) -> Chester Wilkinson | C10: =IF(H10="","",calc!DA129) -> miss | D10: =IF(H10="","",calc!DB129) -> 0 | E10: =IF(H10="","",calc!DC129) -> 0 | F10: =IF(H10="","",calc!DD129) -> 0 | G10: =IF(H10="","",calc!DE129) | H10: =IF(calc!DF129>0,calc!DF129,"") -> 97 | I10: =IF(calc!DG129>0,calc!DG129,"") -> 77 | J10: =calc!DH129
A11: =IF(H11="","",calc!CY130) -> 6 turn | B11: =IF(H11="","",calc!CZ130) -> Alexander Ashley | C11: =IF(H11="","",calc!DA130) -> - | D11: =IF(H11="","",calc!DB130) -> 0 | E11: =IF(H11="","",calc!DC130) -> 21 | F11: =IF(H11="","",calc!DD130) -> 0 | G11: =IF(H11="","",calc!DE130) | H11: =IF(calc!DF130>0,calc!DF130,"") -> 97 | I11: =IF(calc!DG130>0,calc!DG130,"") -> 77 | J11: =calc!DH130
A12: =IF(H12="","",calc!CY131) -> 7 turn | B12: =IF(H12="","",calc!CZ131) -> Chester Wilkinson | C12: =IF(H12="","",calc!DA131) -> - | D12: =IF(H12="","",calc!DB131) -> 26 | E12: =IF(H12="","",calc!DC131) -> 0 | F12: =IF(H12="","",calc!DD131) -> 0 | G12: =IF(H12="","",calc!DE131) | H12: =IF(calc!DF131>0,calc!DF131,"") -> 76 | I12: =IF(calc!DG131>0,calc!DG131,"") -> 77 | J12: =calc!DH131
A13: =IF(H13="","",calc!CY132) -> 8 turn | B13: =IF(H13="","",calc!CZ132) -> Alexander Ashley | C13: =IF(H13="","",calc!DA132) -> miss | D13: =IF(H13="","",calc!DB132) -> 0 | E13: =IF(H13="","",calc!DC132) -> 0 | F13: =IF(H13="","",calc!DD132) -> 0 | G13: =IF(H13="","",calc!DE132) | H13: =IF(calc!DF132>0,calc!DF132,"") -> 76 | I13: =IF(calc!DG132>0,calc!DG132,"") -> 51 | J13: =calc!DH132 | L13: 5 fights
A14: =IF(H14="","",calc!CY133) -> 9 turn | B14: =IF(H14="","",calc!CZ133) -> Chester Wilkinson | C14: =IF(H14="","",calc!DA133) -> miss | D14: =IF(H14="","",calc!DB133) -> 0 | E14: =IF(H14="","",calc!DC133) -> 0 | F14: =IF(H14="","",calc!DD133) -> 0 | G14: =IF(H14="","",calc!DE133) | H14: =IF(calc!DF133>0,calc!DF133,"") -> 76 | I14: =IF(calc!DG133>0,calc!DG133,"") -> 51 | J14: =calc!DH133 | L14: =_xlfn.CONCAT($A$2," WINS") -> Chester Wilkinson WINS | M14: =_xlfn.CONCAT($A$3," WINS") -> Alexander Ashley WINS
A15: =IF(H15="","",calc!CY134) -> 10 turn | B15: =IF(H15="","",calc!CZ134) -> Alexander Ashley | C15: =IF(H15="","",calc!DA134) -> - | D15: =IF(H15="","",calc!DB134) -> 21 | E15: =IF(H15="","",calc!DC134) -> 0 | F15: =IF(H15="","",calc!DD134) -> 0 | G15: =IF(H15="","",calc!DE134) | H15: =IF(calc!DF134>0,calc!DF134,"") -> 76 | I15: =IF(calc!DG134>0,calc!DG134,"") -> 51 | J15: =calc!DH134 | L15: =SUM(AA2:AA6) -> 4 | M15: =SUM(AB2:AB6) -> 1
A16: =IF(H16="","",calc!CY135) -> 11 turn | B16: =IF(H16="","",calc!CZ135) -> Chester Wilkinson | C16: =IF(H16="","",calc!DA135) -> miss | D16: =IF(H16="","",calc!DB135) -> 0 | E16: =IF(H16="","",calc!DC135) -> 0 | F16: =IF(H16="","",calc!DD135) -> 0 | G16: =IF(H16="","",calc!DE135) | H16: =IF(calc!DF135>0,calc!DF135,"") -> 55 | I16: =IF(calc!DG135>0,calc!DG135,"") -> 51 | J16: =calc!DH135 | L16: Crits amount for 5 fights | M16: Hits % for 5 fights
A17: =IF(H17="","",calc!CY136) -> 12 turn | B17: =IF(H17="","",calc!CZ136) -> Alexander Ashley | C17: =IF(H17="","",calc!DA136) -> - | D17: =IF(H17="","",calc!DB136) -> 21 | E17: =IF(H17="","",calc!DC136) -> 0 | F17: =IF(H17="","",calc!DD136) -> 0 | G17: =IF(H17="","",calc!DE136) | H17: =IF(calc!DF136>0,calc!DF136,"") -> 55 | I17: =IF(calc!DG136>0,calc!DG136,"") -> 51 | J17: =calc!DH136 | L17: =50*5-COUNTIF(calc!DE125:DE174,"")-COUNTIF(calc2!DE125:DE174,"")-COUNTIF(calc3!DE125:DE174,"")-COUNTIF(calc4!DE125:DE174,"")-COUNTIF(calc5!DE125:DE174,"") -> 1 | M17: =(COUNTIF(calc!DA125:DA174,"-")+COUNTIF(calc2!DA125:DA174,"-")+COUNTIF(calc3!DA125:DA174,"-")+COUNTIF(calc4!DA125:DA174,"-")+COUNTIF(calc5!DA125:DA174,"-"))/(COUNTIF(calc!DA125:DA174,"-")+COUNTIF(calc2!DA125:DA174,"-")+COUNTIF(calc3!DA125:DA174,"-")+COUNTIF(calc4!DA125:DA174,"-")+COUNTIF(calc5!DA125:DA174,"-")+COUNTIF(calc!DA125:DA174,"miss")+COUNTIF(calc2!DA125:DA174,"miss")+COUNTIF(calc3!DA125:DA174,"miss")+COUNTIF(calc4!DA125:DA174,"miss")+COUNTIF(calc5!DA125:DA174,"miss")) -> 0.42682927
A18: =IF(H18="","",calc!CY137) -> 13 turn | B18: =IF(H18="","",calc!CZ137) -> Chester Wilkinson | C18: =IF(H18="","",calc!DA137) -> miss | D18: =IF(H18="","",calc!DB137) -> 0 | E18: =IF(H18="","",calc!DC137) -> 0 | F18: =IF(H18="","",calc!DD137) -> 0 | G18: =IF(H18="","",calc!DE137) | H18: =IF(calc!DF137>0,calc!DF137,"") -> 34 | I18: =IF(calc!DG137>0,calc!DG137,"") -> 51 | J18: =calc!DH137
A19: =IF(H19="","",calc!CY138) -> 14 turn | B19: =IF(H19="","",calc!CZ138) -> Alexander Ashley | C19: =IF(H19="","",calc!DA138) -> miss | D19: =IF(H19="","",calc!DB138) -> 0 | E19: =IF(H19="","",calc!DC138) -> 0 | F19: =IF(H19="","",calc!DD138) -> 0 | G19: =IF(H19="","",calc!DE138) | H19: =IF(calc!DF138>0,calc!DF138,"") -> 34 | I19: =IF(calc!DG138>0,calc!DG138,"") -> 51 | J19: =calc!DH138
A20: =IF(H20="","",calc!CY139) -> 15 turn | B20: =IF(H20="","",calc!CZ139) -> Chester Wilkinson | C20: =IF(H20="","",calc!DA139) -> - | D20: =IF(H20="","",calc!DB139) -> 0 | E20: =IF(H20="","",calc!DC139) -> 26 | F20: =IF(H20="","",calc!DD139) -> 0 | G20: =IF(H20="","",calc!DE139) | H20: =IF(calc!DF139>0,calc!DF139,"") -> 34 | I20: =IF(calc!DG139>0,calc!DG139,"") -> 51 | J20: =calc!DH139
A21: =IF(H21="","",calc!CY140) -> 16 turn | B21: =IF(H21="","",calc!CZ140) -> Alexander Ashley | C21: =IF(H21="","",calc!DA140) -> - | D21: =IF(H21="","",calc!DB140) -> 21 | E21: =IF(H21="","",calc!DC140) -> 0 | F21: =IF(H21="","",calc!DD140) -> 0 | G21: =IF(H21="","",calc!DE140) | H21: =IF(calc!DF140>0,calc!DF140,"") -> 34 | I21: =IF(calc!DG140>0,calc!DG140,"") -> 25 | J21: =calc!DH140
A22: =IF(H22="","",calc!CY141) -> 17 turn | B22: =IF(H22="","",calc!CZ141) -> Chester Wilkinson | C22: =IF(H22="","",calc!DA141) -> miss | D22: =IF(H22="","",calc!DB141) -> 0 | E22: =IF(H22="","",calc!DC141) -> 0 | F22: =IF(H22="","",calc!DD141) -> 0 | G22: =IF(H22="","",calc!DE141) | H22: =IF(calc!DF141>0,calc!DF141,"") -> 13 | I22: =IF(calc!DG141>0,calc!DG141,"") -> 25 | J22: =calc!DH141
A23: =IF(H23="","",calc!CY142) -> 18 turn | B23: =IF(H23="","",calc!CZ142) -> Alexander Ashley | C23: =IF(H23="","",calc!DA142) -> - | D23: =IF(H23="","",calc!DB142) -> 21 | E23: =IF(H23="","",calc!DC142) -> 0 | F23: =IF(H23="","",calc!DD142) -> 0 | G23: =IF(H23="","",calc!DE142) | H23: =IF(calc!DF142>0,calc!DF142,"") -> 13 | I23: =IF(calc!DG142>0,calc!DG142,"") -> 25 | J23: =calc!DH142
A24: =IF(H24="","",calc!CY143) | B24: =IF(H24="","",calc!CZ143) | C24: =IF(H24="","",calc!DA143) | D24: =IF(H24="","",calc!DB143) | E24: =IF(H24="","",calc!DC143) | F24: =IF(H24="","",calc!DD143) | G24: =IF(H24="","",calc!DE143) | H24: =IF(calc!DF143>0,calc!DF143,"") | I24: =IF(calc!DG143>0,calc!DG143,"") | J24: =calc!DH143 -> Alexander Ashley WINS!
A25: =IF(H25="","",calc!CY144) | B25: =IF(H25="","",calc!CZ144) | C25: =IF(H25="","",calc!DA144) | D25: =IF(H25="","",calc!DB144) | E25: =IF(H25="","",calc!DC144) | F25: =IF(H25="","",calc!DD144) | G25: =IF(H25="","",calc!DE144) | H25: =IF(calc!DF144>0,calc!DF144,"") | I25: =IF(calc!DG144>0,calc!DG144,"") | J25: =calc!DH144
A26: =IF(H26="","",calc!CY145) | B26: =IF(H26="","",calc!CZ145) | C26: =IF(H26="","",calc!DA145) | D26: =IF(H26="","",calc!DB145) | E26: =IF(H26="","",calc!DC145) | F26: =IF(H26="","",calc!DD145) | G26: =IF(H26="","",calc!DE145) | H26: =IF(calc!DF145>0,calc!DF145,"") | I26: =IF(calc!DG145>0,calc!DG145,"") | J26: =calc!DH145
A27: =IF(H27="","",calc!CY146) | B27: =IF(H27="","",calc!CZ146) | C27: =IF(H27="","",calc!DA146) | D27: =IF(H27="","",calc!DB146) | E27: =IF(H27="","",calc!DC146) | F27: =IF(H27="","",calc!DD146) | G27: =IF(H27="","",calc!DE146) | H27: =IF(calc!DF146>0,calc!DF146,"") | I27: =IF(calc!DG146>0,calc!DG146,"") | J27: =calc!DH146
A28: =IF(H28="","",calc!CY147) | B28: =IF(H28="","",calc!CZ147) | C28: =IF(H28="","",calc!DA147) | D28: =IF(H28="","",calc!DB147) | E28: =IF(H28="","",calc!DC147) | F28: =IF(H28="","",calc!DD147) | G28: =IF(H28="","",calc!DE147) | H28: =IF(calc!DF147>0,calc!DF147,"") | I28: =IF(calc!DG147>0,calc!DG147,"") | J28: =calc!DH147
A29: =IF(H29="","",calc!CY148) | B29: =IF(H29="","",calc!CZ148) | C29: =IF(H29="","",calc!DA148) | D29: =IF(H29="","",calc!DB148) | E29: =IF(H29="","",calc!DC148) | F29: =IF(H29="","",calc!DD148) | G29: =IF(H29="","",calc!DE148) | H29: =IF(calc!DF148>0,calc!DF148,"") | I29: =IF(calc!DG148>0,calc!DG148,"") | J29: =calc!DH148
... A55: =IF(H55="","",calc!CY174) | B55: =IF(H55="","",calc!CZ174) | C55: =IF(H55="","",calc!DA174) | D55: =IF(H55="","",calc!DB174) | E55: =IF(H55="","",calc!DC174) | F55: =IF(H55="","",calc!DD174) | G55: =IF(H55="","",calc!DE174) | H55: =IF(calc!DF174>0,calc!DF174,"") | I55: =IF(calc!DG174>0,calc!DG174,"") | J55: =calc!DH174

Sheet Chars
A1: Name | B1: Melee | C1: Agility | D1: Strength | E1: Stamina | F1: Intellect | G1: Instinct | H1: Psionic | I1: Armor | J1: Durability | K1: Force Shield
A2: Adela Tobin | B2: 33 | C2: 25 | D2: 7 | E2: 27 | F2: 7 | G2: 13 | H2: 16 | I2: 36
A3: Aileen Ventura | B3: 28 | C3: 11 | D3: 16 | E3: 10 | F3: 7 | G3: 9 | H3: 6 | J3: 20
A4: Aisha Nicolas | B4: 4 | C4: 24 | D4: 25 | E4: 30 | F4: 22 | G4: 21 | H4: 6 | I4: 33
A5: Aleksandra Mcguire | B5: 16 | C5: 11 | D5: 14 | E5: 5 | F5: 32 | G5: 39 | H5: 15 | J5: 14
A6: Alexander Ashley | B6: 8 | C6: 25 | D6: 21 | E6: 27 | F6: 14 | G6: 6 | H6: 12 | I6: 22
A7: Andrea Richardson | B7: 16 | C7: 4 | D7: 25 | E7: 6 | F7: 9 | G7: 7 | H7: 12 | K7: 5
A8: Barry Snow | B8: 10 | C8: 17 | D8: 26 | E8: 15 | F8: 13 | G8: 37 | H8: 4 | J8: 7
A9: Bryon Jacobs | B9: 15 | C9: 13 | D9: 28 | E9: 14 | F9: 26 | G9: 14 | H9: 7 | I9: 30
A10: Callie Strong | B10: 5 | C10: 18 | D10: 21 | E10: 24 | F10: 25 | G10: 19 | H10: 5 | J10: 31
A11: Cara Poole | B11: 14 | C11: 10 | D11: 10 | E11: 14 | F11: 20 | G11: 34 | H11: 8 | I11: 29
A12: Carina Simpson | B12: 29 | C12: 12 | D12: 33 | E12: 23 | F12: 14 | G12: 5 | H12: 9 | J12: 35
A13: Carl Campbell | B13: 23 | C13: 30 | D13: 30 | E13: 21 | F13: 15 | G13: 24 | H13: 13 | I13: 25
A14: Carmella Nanton | B14: 9 | C14: 5 | D14: 32 | E14: 15 | F14: 4 | G14: 23 | H14: 12 | I14: 23
A15: Carter Umney | B15: 35 | C15: 8 | D15: 33 | E15: 13 | F15: 8 | G15: 8 | H15: 18 | I15: 24
A16: Catherine Murray | B16: 16 | C16: 10 | D16: 23 | E16: 8 | F16: 31 | G16: 9 | H16: 17 | J16: 37
A17: Cecilia Kerr | B17: 25 | C17: 21 | D17: 26 | E17: 10 | F17: 6 | G17: 8 | H17: 7 | K17: 6
A18: Chad Warden | B18: 22 | C18: 17 | D18: 5 | E18: 18 | F18: 38 | G18: 16 | H18: 9 | I18: 23
A19: Chester Wilkinson | B19: 33 | C19: 30 | D19: 26 | E19: 29 | F19: 39 | G19: 39 | H19: 8 | K19: 19
A20: Chris Bingham | B20: 22 | C20: 25 | D20: 32 | E20: 25 | F20: 6 | G20: 29 | H20: 7 | J20: 12
A21: Claire Higgs | B21: 24 | C21: 17 | D21: 5 | E21: 17 | F21: 34 | G21: 26 | H21: 4 | K21: 8
A22: Crystal Reid | B22: 30 | C22: 32 | D22: 30 | E22: 19 | F22: 31 | G22: 20 | H22: 10 | I22: 31
A23: David Pond | B23: 30 | C23: 15 | D23: 7 | E23: 31 | F23: 23 | G23: 35 | H23: 8 | K23: 8
A24: David Rose | B24: 38 | C24: 4 | D24: 11 | E24: 5 | F24: 14 | G24: 31 | H24: 6 | I24: 15
A25: Domenic Cooper | B25: 14 | C25: 12 | D25: 6 | E25: 33 | F25: 36 | G25: 38 | H25: 6 | I25: 19
A26: Eden Robertson | B26: 31 | C26: 24 | D26: 19 | E26: 26 | F26: 12 | G26: 12 | H26: 12 | I26: 34
A27: Eileen Heaton | B27: 14 | C27: 27 | D27: 18 | E27: 9 | F27: 29 | G27: 7 | H27: 8 | K27: 6
A28: Ellen Morgan | B28: 12 | C28: 10 | D28: 15 | E28: 25 | F28: 11 | G28: 9 | H28: 13 | I28: 14
A29: Elly Gibson | B29: 22 | C29: 4 | D29: 27 | E29: 14 | F29: 35 | G29: 21 | H29: 12 | K29: 18
A30: Ember Haines | B30: 31 | C30: 21 | D30: 30 | E30: 33 | F30: 29 | G30: 16 | H30: 17 | I30: 10
A31: Ember Harris | B31: 38 | C31: 10 | D31: 28 | E31: 12 | F31: 24 | G31: 4 | H31: 12 | J31: 11
A32: Emery Phillips | B32: 17 | C32: 8 | D32: 27 | E32: 8 | F32: 18 | G32: 12 | H32: 14 | I32: 2
A33: Enoch Gibbons | B33: 14 | C33: 23 | D33: 17 | E33: 20 | F33: 11 | G33: 20 | H33: 7 | I33: 2
A34: Erick Townend | B34: 21 | C34: 33 | D34: 33 | E34: 22 | F34: 14 | G34: 33 | H34: 9 | J34: 15
A35: Evelynn Varley | B35: 24 | C35: 14 | D35: 23 | E35: 30 | F35: 20 | G35: 33 | H35: 14 | J35: 26
A36: George Rycroft | B36: 32 | C36: 28 | D36: 6 | E36: 23 | F36: 14 | G36: 26 | H36: 8 | I36: 39
A37: Goldie Reading | B37: 16 | C37: 6 | D37: 23 | E37: 33 | F37: 10 | G37: 32 | H37: 13 | K37: 9
A38: Gwenyth Clarkson | B38: 33 | C38: 7 | D38: 28 | E38: 9 | F38: 39 | G38: 34 | H38: 17 | I38: 28
A39: Hanna Moran | B39: 22 | C39: 25 | D39: 18 | E39: 26 | F39: 16 | G39: 14 | H39: 15 | J39: 33
A40: Harriet Mason | B40: 9 | C40: 7 | D40: 6 | E40: 31 | F40: 31 | G40: 27 | H40: 8 | I40: 1
...

Sheet calc
A1: rank\roll | B1: 0 | C1: 1 | D1: 2 | E1: 3 | F1: 4 | G1: 5 | H1: 6 | I1: 7 | J1: 8 | K1: 9 | L1: 10 | M1: 11 | N1: 12 | O1: 13 | P1: 14 | Q1: 15 | R1: 16 | S1: 17 | T1: 18 | U1: 19 | V1: 20 | W1: 21 | X1: 22 | Y1: 23 | Z1: 24 | AA1: 25 | AB1: 26 | AC1: 27 | AD1: 28 | AE1: 29 | AF1: 30 | AG1: 31 | AH1: 32 | AI1: 33 | AJ1: 34 | AK1: 35 | AL1: 36 | AM1: 37 | AN1: 38 | AO1: 39 | AP1: 40 | AQ1: 41 | AR1: 42 | AS1: 43 | AT1: 44 | AU1: 45 | AV1: 46 | AW1: 47 | AX1: 48 | AY1: 49 | AZ1: 50 | BA1: 51 | BB1: 52 | BC1: 53 | BD1: 54 | BE1: 55 | BF1: 56 | BG1: 57 | BH1: 58 | BI1: 59 | BJ1: 60 | BK1: 61 | BL1: 62 | BM1: 63 | BN1: 64 | BO1: 65 | BP1: 66 | BQ1: 67 | BR1: 68 | BS1: 69 | BT1: 70 | BU1: 71 | BV1: 72 | BW1: 73 | BX1: 74 | BY1: 75 | BZ1: 76 | CA1: 77 | CB1: 78 | CC1: 79 | CD1: 80 | CE1: 81 | CF1: 82 | CG1: 83 | CH1: 84 | CI1: 85 | CJ1: 86 | CK1: 87 | CL1: 88 | CM1: 89 | CN1: 90 | CO1: 91 | CP1: 92 | CQ1: 93 | CR1: 94 | CS1: 95 | CT1: 96 | CU1: 97 | CV1: 98 | CW1: 99 | DA1: Melee | DB1: Agility | DC1: Strength | DD1: Stamina | DE1: Intellect | DF1: Instinct | DG1: Psionic
A2: 40 | B2: 0 | C2: 0 | D2: 0 | E2: 0 | F2: 0 | G2: 0 | H2: 0 | I2: 0 | J2: 0 | K2: 0 | L2: 0 | M2: 0 | N2: 0 | O2: 0 | P2: 0 | Q2: 0 | R2: 0 | S2: 0 | T2: 0 | U2: 0 | V2: 0 | W2: 0 | X2: 0 | Y2: 0 | Z2: 0 | AA2: 0 | AB2: 0 | AC2: 0 | AD2: 0 | AE2: 0 | AF2: 1 | AG2: 1 | AH2: 1 | AI2: 1 | AJ2: 1 | AK2: 1 | AL2: 1 | AM2: 1 | AN2: 1 | AO2: 1 | AP2: 1 | AQ2: 1 | AR2: 1 | AS2: 1 | AT2: 1 | AU2: 1 | AV2: 1 | AW2: 1 | AX2: 1 | AY2: 1 | AZ2: 1 | BA2: 1 | BB2: 1 | BC2: 1 | BD2: 1 | BE2: 1 | BF2: 1 | BG2: 1 | BH2: 1 | BI2: 1 | BJ2: 3 | BK2: 3 | BL2: 3 | BM2: 3 | BN2: 3 | BO2: 3 | BP2: 3 | BQ2: 3 | BR2: 3 | BS2: 3 | BT2: 3 | BU2: 3 | BV2: 3 | BW2: 3 | BX2: 3 | BY2: 3 | BZ2: 3 | CA2: 3 | CB2: 3 | CC2: 3 | CD2: 3 | CE2: 3 | CF2: 3 | CG2: 3 | CH2: 3 | CI2: 3 | CJ2: 3 | CK2: 3 | CL2: 3 | CM2: 3 | CN2: 5 | CO2: 5 | CP2: 5 | CQ2: 5 | CR2: 5 | CS2: 5 | CT2: 5 | CU2: 5 | CV2: 5 | CW2: 5 | CZ2: char stat | DA2: 1 | DB2: 10 | DC2: 20 | DD2: 30 | DE2: 40 | DF2: 30 | DG2: 20 | DT2: 0-60 | DU2: suffers | DV2: Nothing | DW2: Direct Hit | DX2: 2 | DY2: None
A3: 39 | B3: 0 | C3: 0 | D3: 0 | E3: 0 | F3: 0 | G3: 0 | H3: 0 | I3: 0 | J3: 0 | K3: 0 | L3: 0 | M3: 0 | N3: 0 | O3: 0 | P3: 0 | Q3: 0 | R3: 0 | S3: 0 | T3: 0 | U3: 0 | V3: 0 | W3: 0 | X3: 0 | Y3: 0 | Z3: 0 | AA3: 0 | AB3: 0 | AC3: 0 | AD3: 0 | AE3: 0 | AF3: 0 | AG3: 0 | AH3: 0 | AI3: 0 | AJ3: 0 | AK3: 1 | AL3: 1 | AM3: 1 | AN3: 1 | AO3: 1 | AP3: 1 | AQ3: 1 | AR3: 1 | AS3: 1 | AT3: 1 | AU3: 1 | AV3: 1 | AW3: 1 | AX3: 1 | AY3: 1 | AZ3: 1 | BA3: 1 | BB3: 1 | BC3: 1 | BD3: 1 | BE3: 1 | BF3: 1 | BG3: 1 | BH3: 1 | BI3: 1 | BJ3: 1 | BK3: 1 | BL3: 1 | BM3: 1 | BN3: 1 | BO3: 3 | BP3: 3 | BQ3: 3 | BR3: 3 | BS3: 3 | BT3: 3 | BU3: 3 | BV3: 3 | BW3: 3 | BX3: 3 | BY3: 3 | BZ3: 3 | CA3: 3 | CB3: 3 | CC3: 3 | CD3: 3 | CE3: 3 | CF3: 3 | CG3: 3 | CH3: 3 | CI3: 3 | CJ3: 3 | CK3: 3 | CL3: 3 | CM3: 3 | CN3: 3 | CO3: 3 | CP3: 3 | CQ3: 3 | CR3: 5 | CS3: 5 | CT3: 5 | CU3: 5 | CV3: 5 | CW3: 5 | CZ3: roll | DA3: 50 | DB3: 20 | DC3: 90 | DD3: 80 | DE3: 70 | DF3: 60 | DG3: 50 | DI3: HPkoef | DT3: 61-70 | DU3: suffers a | DV3: Stamina Penalty - Skip | DW3: Collapsed Lung | DX3: 2 | DY3: 1 round of skipped turns - 1d6 Stamina
A4: 38 | B4: 0 | C4: 0 | D4: 0 | E4: 0 | F4: 0 | G4: 0 | H4: 0 | I4: 0 | J4: 0 | K4: 0 | L4: 0 | M4: 0 | N4: 0 | O4: 0 | P4: 0 | Q4: 0 | R4: 0 | S4: 0 | T4: 0 | U4: 0 | V4: 0 | W4: 0 | X4: 0 | Y4: 0 | Z4: 0 | AA4: 0 | AB4: 0 | AC4: 0 | AD4: 0 | AE4: 0 | AF4: 0 | AG4: 0 | AH4: 0 | AI4: 0 | AJ4: 0 | AK4: 1 | AL4: 1 | AM4: 1 | AN4: 1 | AO4: 1 | AP4: 1 | AQ4: 1 | AR4: 1 | AS4: 1 | AT4: 1 | AU4: 1 | AV4: 1 | AW4: 1 | AX4: 1 | AY4: 1 | AZ4: 1 | BA4: 1 | BB4: 1 | BC4: 1 | BD4: 1 | BE4: 1 | BF4: 1 | BG4: 1 | BH4: 1 | BI4: 1 | BJ4: 1 | BK4: 1 | BL4: 1 | BM4: 1 | BN4: 1 | BO4: 3 | BP4: 3 | BQ4: 3 | BR4: 3 | BS4: 3 | BT4: 3 | BU4: 3 | BV4: 3 | BW4: 3 | BX4: 3 | BY4: 3 | BZ4: 3 | CA4: 3 | CB4: 3 | CC4: 3 | CD4: 3 | CE4: 3 | CF4: 3 | CG4: 3 | CH4: 3 | CI4: 3 | CJ4: 3 | CK4: 3 | CL4: 3 | CM4: 3 | CN4: 3 | CO4: 3 | CP4: 3 | CQ4: 3 | CR4: 5 | CS4: 5 | CT4: 5 | CU4: 5 | CV4: 5 | CW4: 5 | CZ4: result | DA4: =INDEX($B$2:$CW$42, MATCH(DA2,$A$2:$A$42,0), MATCH(DA3,$B$1:$CW$1,0)) -> 0 | DB4: =INDEX($B$2:$CW$42, MATCH(DB2,$A$2:$A$42,0), MATCH(DB3,$B$1:$CW$1,0)) -> 0 | DC4: =INDEX($B$2:$CW$42, MATCH(DC2,$A$2:$A$42,0), MATCH(DC3,$B$1:$CW$1,0)) -> 3 | DD4: =INDEX($B$2:$CW$42, MATCH(DD2,$A$2:$A$42,0), MATCH(DD3,$B$1:$CW$1,0)) -> 3 | DE4: =INDEX($B$2:$CW$42, MATCH(DE2,$A$2:$A$42,0), MATCH(DE3,$B$1:$CW$1,0)) -> 3 | DF4: =INDEX($B$2:$CW$42, MATCH(DF2,$A$2:$A$42,0), MATCH(DF3,$B$1:$CW$1,0)) -> 1 | DG4: =INDEX($B$2:$CW$42, MATCH(DG2,$A$2:$A$42,0), MATCH(DG3,$B$1:$CW$1,0)) -> 1 | DI4: 1 | DT4: 71-80 | DU4: is | DV4: Temp Stat Injury | DW4: Dazed | DX4: 1.5 | DY4: -1d8 Melee Stat reduction for 2 rounds.
A5: 37 | B5: 0 | C5: 0 | D5: 0 | E5: 0 | F5: 0 | G5: 0 | H5: 0 | I5: 0 | J5: 0 | K5: 0 | L5: 0 | M5: 0 | N5: 0 | O5: 0 | P5: 0 | Q5: 0 | R5: 0 | S5: 0 | T5: 0 | U5: 0 | V5: 0 | W5: 0 | X5: 0 | Y5: 0 | Z5: 0 | AA5: 0 | AB5: 0 | AC5: 0 | AD5: 0 | AE5: 0 | AF5: 0 | AG5: 0 | AH5: 0 | AI5: 0 | AJ5: 0 | AK5: 1 | AL5: 1 | AM5: 1 | AN5: 1 | AO5: 1 | AP5: 1 | AQ5: 1 | AR5: 1 | AS5: 1 | AT5: 1 | AU5: 1 | AV5: 1 | AW5: 1 | AX5: 1 | AY5: 1 | AZ5: 1 | BA5: 1 | BB5: 1 | BC5: 1 | BD5: 1 | BE5: 1 | BF5: 1 | BG5: 1 | BH5: 1 | BI5: 1 | BJ5: 1 | BK5: 1 | BL5: 1 | BM5: 1 | BN5: 1 | BO5: 3 | BP5: 3 | BQ5: 3 | BR5: 3 | BS5: 3 | BT5: 3 | BU5: 3 | BV5: 3 | BW5: 3 | BX5: 3 | BY5: 3 | BZ5: 3 | CA5: 3 | CB5: 3 | CC5: 3 | CD5: 3 | CE5: 3 | CF5: 3 | CG5: 3 | CH5: 3 | CI5: 3 | CJ5: 3 | CK5: 3 | CL5: 3 | CM5: 3 | CN5: 3 | CO5: 3 | CP5: 3 | CQ5: 3 | CR5: 5 | CS5: 5 | CT5: 5 | CU5: 5 | CV5: 5 | CW5: 5 | DH5: initiative | DI5: HP | DJ5: Armor | DK5: Durability | DL5: Force Shield | DT5: 81-90 | DU5: suffers a | DV5: Stat Injury | DW5: Broken Rib | DX5: 1.7 | DY5: 1d2 Agility 1d4 Mel
A6: 36 | B6: 0 | C6: 0 | D6: 0 | E6: 0 | F6: 0 | G6: 0 | H6: 0 | I6: 0 | J6: 0 | K6: 0 | L6: 0 | M6: 0 | N6: 0 | O6: 0 | P6: 0 | Q6: 0 | R6: 0 | S6: 0 | T6: 0 | U6: 0 | V6: 0 | W6: 0 | X6: 0 | Y6: 0 | Z6: 0 | AA6: 0 | AB6: 0 | AC6: 0 | AD6: 0 | AE6: 0 | AF6: 0 | AG6: 0 | AH6: 0 | AI6: 0 | AJ6: 0 | AK6: 1 | AL6: 1 | AM6: 1 | AN6: 1 | AO6: 1 | AP6: 1 | AQ6: 1 | AR6: 1 | AS6: 1 | AT6: 1 | AU6: 1 | AV6: 1 | AW6: 1 | AX6: 1 | AY6: 1 | AZ6: 1 | BA6: 1 | BB6: 1 | BC6: 1 | BD6: 1 | BE6: 1 | BF6: 1 | BG6: 1 | BH6: 1 | BI6: 1 | BJ6: 1 | BK6: 1 | BL6: 1 | BM6: 1 | BN6: 1 | BO6: 3 | BP6: 3 | BQ6: 3 | BR6: 3 | BS6: 3 | BT6: 3 | BU6: 3 | BV6: 3 | BW6: 3 | BX6: 3 | BY6: 3 | BZ6: 3 | CA6: 3 | CB6: 3 | CC6: 3 | CD6: 3 | CE6: 3 | CF6: 3 | CG6: 3 | CH6: 3 | CI6: 3 | CJ6: 3 | CK6: 3 | CL6: 3 | CM6: 3 | CN6: 3 | CO6: 3 | CP6: 3 | CQ6: 3 | CR6: 5 | CS6: 5 | CT6: 5 | CU6: 5 | CV6: 5 | CW6: 5 | CZ6: =main!A2 -> Chester Wilkinson | DA6: =SUMIFS(Chars!B$2:B$30,Chars!$A$2:$A$30,calc!$CZ$6) -> 33 | DB6: =SUMIFS(Chars!C$2:C$30,Chars!$A$2:$A$30,calc!$CZ$6) -> 30 | DC6: =SUMIFS(Chars!D$2:D$30,Chars!$A$2:$A$30,calc!$CZ$6) -> 26 | DD6: =SUMIFS(Chars!E$2:E$30,Chars!$A$2:$A$30,calc!$CZ$6) -> 29 | DE6: =SUMIFS(Chars!F$2:F$30,Chars!$A$2:$A$30,calc!$CZ$6) -> 39 | DF6: =SUMIFS(Chars!G$2:G$30,Chars!$A$2:$A$30,calc!$CZ$6) -> 39 | DG6: =SUMIFS(Chars!H$2:H$30,Chars!$A$2:$A$30,calc!$CZ$6) -> 8 | DH6: =DA6+DB6+DE6+DF6 -> 141 | DI6: =$DI$4*(DA6+DB6+DC6+DD6) -> 118 | DJ6: =SUMIFS(Chars!I$2:I$30,Chars!$A$2:$A$30,calc!$CZ$6) -> 0 | DK6: =SUMIFS(Chars!J$2:J$30,Chars!$A$2:$A$30,calc!$CZ$6) -> 0 | DL6: =SUMIFS(Chars!K$2:K$30,Chars!$A$2:$A$30,calc!$CZ$6) -> 19 | DT6: 91-99 | DU6: is | DV6: Skipped Turn | DW6: Knocked Out Briefly | DX6: 1.5 | DY6: 3 skipped turns
A7: 35 | B7: 0 | C7: 0 | D7: 0 | E7: 0 | F7: 0 | G7: 0 | H7: 0 | I7: 0 | J7: 0 | K7: 0 | L7: 0 | M7: 0 | N7: 0 | O7: 0 | P7: 0 | Q7: 0 | R7: 0 | S7: 0 | T7: 0 | U7: 0 | V7: 0 | W7: 0 | X7: 0 | Y7: 0 | Z7: 0 | AA7: 0 | AB7: 0 | AC7: 0 | AD7: 0 | AE7: 0 | AF7: 0 | AG7: 0 | AH7: 0 | AI7: 0 | AJ7: 0 | AK7: 1 | AL7: 1 | AM7: 1 | AN7: 1 | AO7: 1 | AP7: 1 | AQ7: 1 | AR7: 1 | AS7: 1 | AT7: 1 | AU7: 1 | AV7: 1 | AW7: 1 | AX7: 1 | AY7: 1 | AZ7: 1 | BA7: 1 | BB7: 1 | BC7: 1 | BD7: 1 | BE7: 1 | BF7: 1 | BG7: 1 | BH7: 1 | BI7: 1 | BJ7: 1 | BK7: 1 | BL7: 1 | BM7: 1 | BN7: 1 | BO7: 3 | BP7: 3 | BQ7: 3 | BR7: 3 | BS7: 3 | BT7: 3 | BU7: 3 | BV7: 3 | BW7: 3 | BX7: 3 | BY7: 3 | BZ7: 3 | CA7: 3 | CB7: 3 | CC7: 3 | CD7: 3 | CE7: 3 | CF7: 3 | CG7: 3 | CH7: 3 | CI7: 3 | CJ7: 3 | CK7: 3 | CL7: 3 | CM7: 3 | CN7: 3 | CO7: 3 | CP7: 3 | CQ7: 3 | CR7: 5 | CS7: 5 | CT7: 5 | CU7: 5 | CV7: 5 | CW7: 5 | CZ7: =main!A3 -> Alexander Ashley | DA7: =SUMIFS(Chars!B$2:B$30,Chars!$A$2:$A$30,calc!$CZ$7) -> 8 | DB7: =SUMIFS(Chars!C$2:C$30,Chars!$A$2:$A$30,calc!$CZ$7) -> 25 | DC7: =SUMIFS(Chars!D$2:D$30,Chars!$A$2:$A$30,calc!$CZ$7) -> 21 | DD7: =SUMIFS(Chars!E$2:E$30,Chars!$A$2:$A$30,calc!$CZ$7) -> 27 | DE7: =SUMIFS(Chars!F$2:F$30,Chars!$A$2:$A$30,calc!$CZ$7) -> 14 | DF7: =SUMIFS(Chars!G$2:G$30,Chars!$A$2:$A$30,calc!$CZ$7) -> 6 | DG7: =SUMIFS(Chars!H$2:H$30,Chars!$A$2:$A$30,calc!$CZ$7) -> 12 | DH7: =DA7+DB7+DE7+DF7 -> 53 | DI7: =$DI$4*(DA7+DB7+DC7+DD7) -> 81 | DJ7: =SUMIFS(Chars!I$2:I$30,Chars!$A$2:$A$30,calc!$CZ$7) -> 22 | DK7: =SUMIFS(Chars!J$2:J$30,Chars!$A$2:$A$30,calc!$CZ$7) -> 0 | DL7: =SUMIFS(Chars!K$2:K$30,Chars!$A$2:$A$30,calc!$CZ$7) -> 0 | DT7: Roll | DU7: Crit | DV7: Crit eff
A8: 34 | B8: 0 | C8: 0 | D8: 0 | E8: 0 | F8: 0 | G8: 0 | H8: 0 | I8: 0 | J8: 0 | K8: 0 | L8: 0 | M8: 0 | N8: 0 | O8: 0 | P8: 0 | Q8: 0 | R8: 0 | S8: 0 | T8: 0 | U8: 0 | V8: 0 | W8: 0 | X8: 0 | Y8: 0 | Z8: 0 | AA8: 0 | AB8: 0 | AC8: 0 | AD8: 0 | AE8: 0 | AF8: 0 | AG8: 0 | AH8: 0 | AI8: 0 | AJ8: 0 | AK8: 1 | AL8: 1 | AM8: 1 | AN8: 1 | AO8: 1 | AP8: 1 | AQ8: 1 | AR8: 1 | AS8: 1 | AT8: 1 | AU8: 1 | AV8: 1 | AW8: 1 | AX8: 1 | AY8: 1 | AZ8: 1 | BA8: 1 | BB8: 1 | BC8: 1 | BD8: 1 | BE8: 1 | BF8: 1 | BG8: 1 | BH8: 1 | BI8: 1 | BJ8: 1 | BK8: 1 | BL8: 1 | BM8: 1 | BN8: 1 | BO8: 3 | BP8: 3 | BQ8: 3 | BR8: 3 | BS8: 3 | BT8: 3 | BU8: 3 | BV8: 3 | BW8: 3 | BX8: 3 | BY8: 3 | BZ8: 3 | CA8: 3 | CB8: 3 | CC8: 3 | CD8: 3 | CE8: 3 | CF8: 3 | CG8: 3 | CH8: 3 | CI8: 3 | CJ8: 3 | CK8: 3 | CL8: 3 | CM8: 3 | CN8: 3 | CO8: 3 | CP8: 3 | CQ8: 3 | CR8: 5 | CS8: 5 | CT8: 5 | CU8: 5 | CV8: 5 | CW8: 5 | DT8: 0 | DU8: 2 | DV8: Direct Hit
A9: 33 | B9: 0 | C9: 0 | D9: 0 | E9: 0 | F9: 0 | G9: 0 | H9: 0 | I9: 0 | J9: 0 | K9: 0 | L9: 0 | M9: 0 | N9: 0 | O9: 0 | P9: 0 | Q9: 0 | R9: 0 | S9: 0 | T9: 0 | U9: 0 | V9: 0 | W9: 0 | X9: 0 | Y9: 0 | Z9: 0 | AA9: 0 | AB9: 0 | AC9: 0 | AD9: 0 | AE9: 0 | AF9: 0 | AG9: 0 | AH9: 0 | AI9: 0 | AJ9: 0 | AK9: 1 | AL9: 1 | AM9: 1 | AN9: 1 | AO9: 1 | AP9: 1 | AQ9: 1 | AR9: 1 | AS9: 1 | AT9: 1 | AU9: 1 | AV9: 1 | AW9: 1 | AX9: 1 | AY9: 1 | AZ9: 1 | BA9: 1 | BB9: 1 | BC9: 1 | BD9: 1 | BE9: 1 | BF9: 1 | BG9: 1 | BH9: 1 | BI9: 1 | BJ9: 1 | BK9: 1 | BL9: 1 | BM9: 1 | BN9: 1 | BO9: 3 | BP9: 3 | BQ9: 3 | BR9: 3 | BS9: 3 | BT9: 3 | BU9: 3 | BV9: 3 | BW9: 3 | BX9: 3 | BY9: 3 | BZ9: 3 | CA9: 3 | CB9: 3 | CC9: 3 | CD9: 3 | CE9: 3 | CF9: 3 | CG9: 3 | CH9: 3 | CI9: 3 | CJ9: 3 | CK9: 3 | CL9: 3 | CM9: 3 | CN9: 3 | CO9: 3 | CP9: 3 | CQ9: 3 | CR9: 5 | CS9: 5 | CT9: 5 | CU9: 5 | CV9: 5 | CW9: 5 | DP9: Defender's | DQ9: Attack's Column Shift | DT9: 1 | DU9: 2 | DV9: Direct Hit
A10: 32 | B10: 0 | C10: 0 | D10: 0 | E10: 0 | F10: 0 | G10: 0 | H10: 0 | I10: 0 | J10: 0 | K10: 0 | L10: 0 | M10: 0 | N10: 0 | O10: 0 | P10: 0 | Q10: 0 | R10: 0 | S10: 0 | T10: 0 | U10: 0 | V10: 0 | W10: 0 | X10: 0 | Y10: 0 | Z10: 0 | AA10: 0 | AB10: 0 | AC10: 0 | AD10: 0 | AE10: 0 | AF10: 0 | AG10: 0 | AH10: 0 | AI10: 0 | AJ10: 0 | AK10: 1 | AL10: 1 | AM10: 1 | AN10: 1 | AO10: 1 | AP10: 1 | AQ10: 1 | AR10: 1 | AS10: 1 | AT10: 1 | AU10: 1 | AV10: 1 | AW10: 1 | AX10: 1 | AY10: 1 | AZ10: 1 | BA10: 1 | BB10: 1 | BC10: 1 | BD10: 1 | BE10: 1 | BF10: 1 | BG10: 1 | BH10: 1 | BI10: 1 | BJ10: 1 | BK10: 1 | BL10: 1 | BM10: 1 | BN10: 1 | BO10: 3 | BP10: 3 | BQ10: 3 | BR10: 3 | BS10: 3 | BT10: 3 | BU10: 3 | BV10: 3 | BW10: 3 | BX10: 3 | BY10: 3 | BZ10: 3 | CA10: 3 | CB10: 3 | CC10: 3 | CD10: 3 | CE10: 3 | CF10: 3 | CG10: 3 | CH10: 3 | CI10: 3 | CJ10: 3 | CK10: 3 | CL10: 3 | CM10: 3 | CN10: 3 | CO10: 3 | CP10: 3 | CQ10: 3 | CR10: 5 | CS10: 5 | CT10: 5 | CU10: 5 | CV10: 5 | CW10: 5 | DA10: stats roll table | DH10: Crit roll | DI10: Dodge -CS | DJ10: DMG | DT10: 2 | DU10: 2 | DV10: Direct Hit
A11: 31 | B11: 0 | C11: 0 | D11: 0 | E11: 0 | F11: 0 | G11: 0 | H11: 0 | I11: 0 | J11: 0 | K11: 0 | L11: 0 | M11: 0 | N11: 0 | O11: 0 | P11: 0 | Q11: 0 | R11: 0 | S11: 0 | T11: 0 | U11: 0 | V11: 0 | W11: 0 | X11: 0 | Y11: 0 | Z11: 0 | AA11: 0 | AB11: 0 | AC11: 0 | AD11: 0 | AE11: 0 | AF11: 0 | AG11: 0 | AH11: 0 | AI11: 0 | AJ11: 0 | AK11: 1 | AL11: 1 | AM11: 1 | AN11: 1 | AO11: 1 | AP11: 1 | AQ11: 1 | AR11: 1 | AS11: 1 | AT11: 1 | AU11: 1 | AV11: 1 | AW11: 1 | AX11: 1 | AY11: 1 | AZ11: 1 | BA11: 1 | BB11: 1 | BC11: 1 | BD11: 1 | BE11: 1 | BF11: 1 | BG11: 1 | BH11: 1 | BI11: 1 | BJ11: 1 | BK11: 1 | BL11: 1 | BM11: 1 | BN11: 1 | BO11: 3 | BP11: 3 | BQ11: 3 | BR11: 3 | BS11: 3 | BT11: 3 | BU11: 3 | BV11: 3 | BW11: 3 | BX11: 3 | BY11: 3 | BZ11: 3 | CA11: 3 | CB11: 3 | CC11: 3 | CD11: 3 | CE11: 3 | CF11: 3 | CG11: 3 | CH11: 3 | CI11: 3 | CJ11: 3 | CK11: 3 | CL11: 3 | CM11: 3 | CN11: 3 | CO11: 3 | CP11: 3 | CQ11: 3 | CR11: 5 | CS11: 5 | CT11: 5 | CU11: 5 | CV11: 5 | CW11: 5 | CY11: 1 turn | CZ11: =$CZ$6 -> Chester Wilkinson | DA11: =RANDBETWEEN(0,99) -> 46 | DB11: =RANDBETWEEN(0,99) -> 71 | DC11: =RANDBETWEEN(0,99) -> 44 | DD11: =RANDBETWEEN(0,99) -> 25 | DE11: =RANDBETWEEN(0,99) -> 84 | DF11: =RANDBETWEEN(0,99) -> 87 | DG11: =RANDBETWEEN(0,99) -> 70 | DH11: =RANDBETWEEN(0,99) -> 77 | DI11: =SUMIFS($DS$31:$DS$111,$DR$31:$DR$111,DB$6+DF$6) -> -4 | DJ11: =$DC$6 -> 26 | DP11: Agility | DT11: 3 | DU11: 2 | DV11: Direct Hit
A12: 30 | B12: 0 | C12: 0 | D12: 0 | E12: 0 | F12: 0 | G12: 0 | H12: 0 | I12: 0 | J12: 0 | K12: 0 | L12: 0 | M12: 0 | N12: 0 | O12: 0 | P12: 0 | Q12: 0 | R12: 0 | S12: 0 | T12: 0 | U12: 0 | V12: 0 | W12: 0 | X12: 0 | Y12: 0 | Z12: 0 | AA12: 0 | AB12: 0 | AC12: 0 | AD12: 0 | AE12: 0 | AF12: 0 | AG12: 0 | AH12: 0 | AI12: 0 | AJ12: 0 | AK12: 1 | AL12: 1 | AM12: 1 | AN12: 1 | AO12: 1 | AP12: 1 | AQ12: 1 | AR12: 1 | AS12: 1 | AT12: 1 | AU12: 1 | AV12: 1 | AW12: 1 | AX12: 1 | AY12: 1 | AZ12: 1 | BA12: 1 | BB12: 1 | BC12: 1 | BD12: 1 | BE12: 1 | BF12: 1 | BG12: 1 | BH12: 1 | BI12: 1 | BJ12: 1 | BK12: 1 | BL12: 1 | BM12: 1 | BN12: 1 | BO12: 3 | BP12: 3 | BQ12: 3 | BR12: 3 | BS12: 3 | BT12: 3 | BU12: 3 | BV12: 3 | BW12: 3 | BX12: 3 | BY12: 3 | BZ12: 3 | CA12: 3 | CB12: 3 | CC12: 3 | CD12: 3 | CE12: 3 | CF12: 3 | CG12: 3 | CH12: 3 | CI12: 3 | CJ12: 3 | CK12: 3 | CL12: 3 | CM12: 3 | CN12: 3 | CO12: 3 | CP12: 3 | CQ12: 3 | CR12: 5 | CS12: 5 | CT12: 5 | CU12: 5 | CV12: 5 | CW12: 5 | CY12: 2 turn | CZ12: =$CZ$7 -> Alexander Ashley | DA12: =RANDBETWEEN(0,99) -> 67 | DB12: =RANDBETWEEN(0,99) -> 82 | DC12: =RANDBETWEEN(0,99) -> 92 | DD12: =RANDBETWEEN(0,99) -> 7 | DE12: =RANDBETWEEN(0,99) -> 11 | DF12: =RANDBETWEEN(0,99) -> 90 | DG12: =RANDBETWEEN(0,99) -> 9 | DH12: =RANDBETWEEN(0,99) -> 39 | DI12: =SUMIFS($DS$31:$DS$111,$DR$31:$DR$111,DB$7+DF$7) -> -2 | DJ12: =$DC$7 -> 21 | DT12: 4 | DU12: 2 | DV12: Direct Hit
A13: 29 | B13: 0 | C13: 0 | D13: 0 | E13: 0 | F13: 0 | G13: 0 | H13: 0 | I13: 0 | J13: 0 | K13: 0 | L13: 0 | M13: 0 | N13: 0 | O13: 0 | P13: 0 | Q13: 0 | R13: 0 | S13: 0 | T13: 0 | U13: 0 | V13: 0 | W13: 0 | X13: 0 | Y13: 0 | Z13: 0 | AA13: 0 | AB13: 0 | AC13: 0 | AD13: 0 | AE13: 0 | AF13: 0 | AG13: 0 | AH13: 0 | AI13: 0 | AJ13: 0 | AK13: 0 | AL13: 0 | AM13: 0 | AN13: 0 | AO13: 0 | AP13: 1 | AQ13: 1 | AR13: 1 | AS13: 1 | AT13: 1 | AU13: 1 | AV13: 1 | AW13: 1 | AX13: 1 | AY13: 1 | AZ13: 1 | BA13: 1 | BB13: 1 | BC13: 1 | BD13: 1 | BE13: 1 | BF13: 1 | BG13: 1 | BH13: 1 | BI13: 1 | BJ13: 1 | BK13: 1 | BL13: 1 | BM13: 1 | BN13: 1 | BO13: 1 | BP13: 1 | BQ13: 1 | BR13: 1 | BS13: 1 | BT13: 3 | BU13: 3 | BV13: 3 | BW13: 3 | BX13: 3 | BY13: 3 | BZ13: 3 | CA13: 3 | CB13: 3 | CC13: 3 | CD13: 3 | CE13: 3 | CF13: 3 | CG13: 3 | CH13: 3 | CI13: 3 | CJ13: 3 | CK13: 3 | CL13: 3 | CM13: 3 | CN13: 3 | CO13: 3 | CP13: 3 | CQ13: 3 | CR13: 5 | CS13: 5 | CT13: 5 | CU13: 5 | CV13: 5 | CW13: 5 | CY13: 3 turn | CZ13: =$CZ$6 -> Chester Wilkinson | DA13: =RANDBETWEEN(0,99) -> 60 | DB13: =RANDBETWEEN(0,99) -> 61 | DC13: =RANDBETWEEN(0,99) -> 30 | DD13: =RANDBETWEEN(0,99) -> 1 | DE13: =RANDBETWEEN(0,99) -> 3 | DF13: =RANDBETWEEN(0,99) -> 2 | DG13: =RANDBETWEEN(0,99) -> 18 | DH13: =RANDBETWEEN(0,99) -> 46 | DI13: =SUMIFS($DS$31:$DS$111,$DR$31:$DR$111,DB$6+DF$6) -> -4 | DJ13: =$DC$6 -> 26 | DP13: Rank | DT13: 5 | DU13: 2 | DV13: Direct Hit
A14: 28 | B14: 0 | C14: 0 | D14: 0 | E14: 0 | F14: 0 | G14: 0 | H14: 0 | I14: 0 | J14: 0 | K14: 0 | L14: 0 | M14: 0 | N14: 0 | O14: 0 | P14: 0 | Q14: 0 | R14: 0 | S14: 0 | T14: 0 | U14: 0 | V14: 0 | W14: 0 | X14: 0 | Y14: 0 | Z14: 0 | AA14: 0 | AB14: 0 | AC14: 0 | AD14: 0 | AE14: 0 | AF14: 0 | AG14: 0 | AH14: 0 | AI14: 0 | AJ14: 0 | AK14: 0 | AL14: 0 | AM14: 0 | AN14: 0 | AO14: 0 | AP14: 1 | AQ14: 1 | AR14: 1 | AS14: 1 | AT14: 1 | AU14: 1 | AV14: 1 | AW14: 1 | AX14: 1 | AY14: 1 | AZ14: 1 | BA14: 1 | BB14: 1 | BC14: 1 | BD14: 1 | BE14: 1 | BF14: 1 | BG14: 1 | BH14: 1 | BI14: 1 | BJ14: 1 | BK14: 1 | BL14: 1 | BM14: 1 | BN14: 1 | BO14: 1 | BP14: 1 | BQ14: 1 | BR14: 1 | BS14: 1 | BT14: 3 | BU14: 3 | BV14: 3 | BW14: 3 | BX14: 3 | BY14: 3 | BZ14: 3 | CA14: 3 | CB14: 3 | CC14: 3 | CD14: 3 | CE14: 3 | CF14: 3 | CG14: 3 | CH14: 3 | CI14: 3 | CJ14: 3 | CK14: 3 | CL14: 3 | CM14: 3 | CN14: 3 | CO14: 3 | CP14: 3 | CQ14: 3 | CR14: 5 | CS14: 5 | CT14: 5 | CU14: 5 | CV14: 5 | CW14: 5 | CY14: 4 turn | CZ14: =$CZ$7 -> Alexander Ashley | DA14: =RANDBETWEEN(0,99) -> 59 | DB14: =RANDBETWEEN(0,99) -> 35 | DC14: =RANDBETWEEN(0,99) -> 93 | DD14: =RANDBETWEEN(0,99) -> 10 | DE14: =RANDBETWEEN(0,99) -> 57 | DF14: =RANDBETWEEN(0,99) -> 23 | DG14: =RANDBETWEEN(0,99) -> 11 | DH14: =RANDBETWEEN(0,99) -> 0 | DI14: =SUMIFS($DS$31:$DS$111,$DR$31:$DR$111,DB$7+DF$7) -> -2 | DJ14: =$DC$7 -> 21 | DP14: None-9 | DQ14: Unable to dodge | DT14: 6 | DU14: 2 | DV14: Direct Hit
A15: 27 | B15: 0 | C15: 0 | D15: 0 | E15: 0 | F15: 0 | G15: 0 | H15: 0 | I15: 0 | J15: 0 | K15: 0 | L15: 0 | M15: 0 | N15: 0 | O15: 0 | P15: 0 | Q15: 0 | R15: 0 | S15: 0 | T15: 0 | U15: 0 | V15: 0 | W15: 0 | X15: 0 | Y15: 0 | Z15: 0 | AA15: 0 | AB15: 0 | AC15: 0 | AD15: 0 | AE15: 0 | AF15: 0 | AG15: 0 | AH15: 0 | AI15: 0 | AJ15: 0 | AK15: 0 | AL15: 0 | AM15: 0 | AN15: 0 | AO15: 0 | AP15: 1 | AQ15: 1 | AR15: 1 | AS15: 1 | AT15: 1 | AU15: 1 | AV15: 1 | AW15: 1 | AX15: 1 | AY15: 1 | AZ15: 1 | BA15: 1 | BB15: 1 | BC15: 1 | BD15: 1 | BE15: 1 | BF15: 1 | BG15: 1 | BH15: 1 | BI15: 1 | BJ15: 1 | BK15: 1 | BL15: 1 | BM15: 1 | BN15: 1 | BO15: 1 | BP15: 1 | BQ15: 1 | BR15: 1 | BS15: 1 | BT15: 3 | BU15: 3 | BV15: 3 | BW15: 3 | BX15: 3 | BY15: 3 | BZ15: 3 | CA15: 3 | CB15: 3 | CC15: 3 | CD15: 3 | CE15: 3 | CF15: 3 | CG15: 3 | CH15: 3 | CI15: 3 | CJ15: 3 | CK15: 3 | CL15: 3 | CM15: 3 | CN15: 3 | CO15: 3 | CP15: 3 | CQ15: 3 | CR15: 5 | CS15: 5 | CT15: 5 | CU15: 5 | CV15: 5 | CW15: 5 | CY15: 5 turn | CZ15: =$CZ$6 -> Chester Wilkinson | DA15: =RANDBETWEEN(0,99) -> 4 | DB15: =RANDBETWEEN(0,99) -> 71 | DC15: =RANDBETWEEN(0,99) -> 83 | DD15: =RANDBETWEEN(0,99) -> 92 | DE15: =RANDBETWEEN(0,99) -> 54 | DF15: =RANDBETWEEN(0,99) -> 89 | DG15: =RANDBETWEEN(0,99) -> 72 | DH15: =RANDBETWEEN(0,99) -> 45 | DI15: =SUMIFS($DS$31:$DS$111,$DR$31:$DR$111,DB$6+DF$6) -> -4 | DJ15: =$DC$6 -> 26 | DP15: 10-19 | DQ15: -1CS | DT15: 7 | DU15: 2 | DV15: Direct Hit
A16: 26 | B16: 0 | C16: 0 | D16: 0 | E16: 0 | F16: 0 | G16: 0 | H16: 0 | I16: 0 | J16: 0 | K16: 0 | L16: 0 | M16: 0 | N16: 0 | O16: 0 | P16: 0 | Q16: 0 | R16: 0 | S16: 0 | T16: 0 | U16: 0 | V16: 0 | W16: 0 | X16: 0 | Y16: 0 | Z16: 0 | AA16: 0 | AB16: 0 | AC16: 0 | AD16: 0 | AE16: 0 | AF16: 0 | AG16: 0 | AH16: 0 | AI16: 0 | AJ16: 0 | AK16: 0 | AL16: 0 | AM16: 0 | AN16: 0 | AO16: 0 | AP16: 1 | AQ16: 1 | AR16: 1 | AS16: 1 | AT16: 1 | AU16: 1 | AV16: 1 | AW16: 1 | AX16: 1 | AY16: 1 | AZ16: 1 | BA16: 1 | BB16: 1 | BC16: 1 | BD16: 1 | BE16: 1 | BF16: 1 | BG16: 1 | BH16: 1 | BI16: 1 | BJ16: 1 | BK16: 1 | BL16: 1 | BM16: 1 | BN16: 1 | BO16: 1 | BP16: 1 | BQ16: 1 | BR16: 1 | BS16: 1 | BT16: 3 | BU16: 3 | BV16: 3 | BW16: 3 | BX16: 3 | BY16: 3 | BZ16: 3 | CA16: 3 | CB16: 3 | CC16: 3 | CD16: 3 | CE16: 3 | CF16: 3 | CG16: 3 | CH16: 3 | CI16: 3 | CJ16: 3 | CK16: 3 | CL16: 3 | CM16: 3 | CN16: 3 | CO16: 3 | CP16: 3 | CQ16: 3 | CR16: 5 | CS16: 5 | CT16: 5 | CU16: 5 | CV16: 5 | CW16: 5 | CY16: 6 turn | CZ16: =$CZ$7 -> Alexander Ashley | DA16: =RANDBETWEEN(0,99) -> 97 | DB16: =RANDBETWEEN(0,99) -> 87 | DC16: =RANDBETWEEN(0,99) -> 54 | DD16: =RANDBETWEEN(0,99) -> 41 | DE16: =RANDBETWEEN(0,99) -> 71 | DF16: =RANDBETWEEN(0,99) -> 33 | DG16: =RANDBETWEEN(0,99) -> 71 | DH16: =RANDBETWEEN(0,99) -> 27 | DI16: =SUMIFS($DS$31:$DS$111,$DR$31:$DR$111,DB$7+DF$7) -> -2 | DJ16: =$DC$7 -> 21 | DP16: 20-29 | DQ16: -2CS | DT16: 8 | DU16: 2 | DV16: Direct Hit
A17: 25 | B17: 0 | C17: 0 | D17: 0 | E17: 0 | F17: 0 | G17: 0 | H17: 0 | I17: 0 | J17: 0 | K17: 0 | L17: 0 | M17: 0 | N17: 0 | O17: 0 | P17: 0 | Q17: 0 | R17: 0 | S17: 0 | T17: 0 | U17: 0 | V17: 0 | W17: 0 | X17: 0 | Y17: 0 | Z17: 0 | AA17: 0 | AB17: 0 | AC17: 0 | AD17: 0 | AE17: 0 | AF17: 0 | AG17: 0 | AH17: 0 | AI17: 0 | AJ17: 0 | AK17: 0 | AL17: 0 | AM17: 0 | AN17: 0 | AO17: 0 | AP17: 1 | AQ17: 1 | AR17: 1 | AS17: 1 | AT17: 1 | AU17: 1 | AV17: 1 | AW17: 1 | AX17: 1 | AY17: 1 | AZ17: 1 | BA17: 1 | BB17: 1 | BC17: 1 | BD17: 1 | BE17: 1 | BF17: 1 | BG17: 1 | BH17: 1 | BI17: 1 | BJ17: 1 | BK17: 1 | BL17: 1 | BM17: 1 | BN17: 1 | BO17: 1 | BP17: 1 | BQ17: 1 | BR17: 1 | BS17: 1 | BT17: 3 | BU17: 3 | BV17: 3 | BW17: 3 | BX17: 3 | BY17: 3 | BZ17: 3 | CA17: 3 | CB17: 3 | CC17: 3 | CD17: 3 | CE17: 3 | CF17: 3 | CG17: 3 | CH17: 3 | CI17: 3 | CJ17: 3 | CK17: 3 | CL17: 3 | CM17: 3 | CN17: 3 | CO17: 3 | CP17: 3 | CQ17: 3 | CR17: 5 | CS17: 5 | CT17: 5 | CU17: 5 | CV17: 5 | CW17: 5 | CY17: 7 turn | CZ17: =$CZ$6 -> Chester Wilkinson | DA17: =RANDBETWEEN(0,99) -> 57 | DB17: =RANDBETWEEN(0,99) -> 9 | DC17: =RANDBETWEEN(0,99) -> 5 | DD17: =RANDBETWEEN(0,99) -> 4 | DE17: =RANDBETWEEN(0,99) -> 95 | DF17: =RANDBETWEEN(0,99) -> 67 | DG17: =RANDBETWEEN(0,99) -> 76 | DH17: =RANDBETWEEN(0,99) -> 36 | DI17: =SUMIFS($DS$31:$DS$111,$DR$31:$DR$111,DB$6+DF$6) -> -4 | DJ17: =$DC$6 -> 26 | DP17: 30-39 | DQ17: -3CS | DT17: 9 | DU17: 2 | DV17: Direct Hit
A18: 24 | B18: 0 | C18: 0 | D18: 0 | E18: 0 | F18: 0 | G18: 0 | H18: 0 | I18: 0 | J18: 0 | K18: 0 | L18: 0 | M18: 0 | N18: 0 | O18: 0 | P18: 0 | Q18: 0 | R18: 0 | S18: 0 | T18: 0 | U18: 0 | V18: 0 | W18: 0 | X18: 0 | Y18: 0 | Z18: 0 | AA18: 0 | AB18: 0 | AC18: 0 | AD18: 0 | AE18: 0 | AF18: 0 | AG18: 0 | AH18: 0 | AI18: 0 | AJ18: 0 | AK18: 0 | AL18: 0 | AM18: 0 | AN18: 0 | AO18: 0 | AP18: 1 | AQ18: 1 | AR18: 1 | AS18: 1 | AT18: 1 | AU18: 1 | AV18: 1 | AW18: 1 | AX18: 1 | AY18: 1 | AZ18: 1 | BA18: 1 | BB18: 1 | BC18: 1 | BD18: 1 | BE18: 1 | BF18: 1 | BG18: 1 | BH18: 1 | BI18: 1 | BJ18: 1 | BK18: 1 | BL18: 1 | BM18: 1 | BN18: 1 | BO18: 1 | BP18: 1 | BQ18: 1 | BR18: 1 | BS18: 1 | BT18: 3 | BU18: 3 | BV18: 3 | BW18: 3 | BX18: 3 | BY18: 3 | BZ18: 3 | CA18: 3 | CB18: 3 | CC18: 3 | CD18: 3 | CE18: 3 | CF18: 3 | CG18: 3 | CH18: 3 | CI18: 3 | CJ18: 3 | CK18: 3 | CL18: 3 | CM18: 3 | CN18: 3 | CO18: 3 | CP18: 3 | CQ18: 3 | CR18: 5 | CS18: 5 | CT18: 5 | CU18: 5 | CV18: 5 | CW18: 5 | CY18: 8 turn | CZ18: =$CZ$7 -> Alexander Ashley | DA18: =RANDBETWEEN(0,99) -> 40 | DB18: =RANDBETWEEN(0,99) -> 78 | DC18: =RANDBETWEEN(0,99) -> 89 | DD18: =RANDBETWEEN(0,99) -> 67 | DE18: =RANDBETWEEN(0,99) -> 1 | DF18: =RANDBETWEEN(0,99) -> 79 | DG18: =RANDBETWEEN(0,99) -> 13 | DH18: =RANDBETWEEN(0,99) -> 96 | DI18: =SUMIFS($DS$31:$DS$111,$DR$31:$DR$111,DB$7+DF$7) -> -2 | DJ18: =$DC$7 -> 21 | DP18: 40-49 | DQ18: -4CS | DT18: 10 | DU18: 2 | DV18: Direct Hit
A19: 23 | B19: 0 | C19: 0 | D19: 0 | E19: 0 | F19: 0 | G19: 0 | H19: 0 | I19: 0 | J19: 0 | K19: 0 | L19: 0 | M19: 0 | N19: 0 | O19: 0 | P19: 0 | Q19: 0 | R19: 0 | S19: 0 | T19: 0 | U19: 0 | V19: 0 | W19: 0 | X19: 0 | Y19: 0 | Z19: 0 | AA19: 0 | AB19: 0 | AC19: 0 | AD19: 0 | AE19: 0 | AF19: 0 | AG19: 0 | AH19: 0 | AI19: 0 | AJ19: 0 | AK19: 0 | AL19: 0 | AM19: 0 | AN19: 0 | AO19: 0 | AP19: 1 | AQ19: 1 | AR19: 1 | AS19: 1 | AT19: 1 | AU19: 1 | AV19: 1 | AW19: 1 | AX19: 1 | AY19: 1 | AZ19: 1 | BA19: 1 | BB19: 1 | BC19: 1 | BD19: 1 | BE19: 1 | BF19: 1 | BG19: 1 | BH19: 1 | BI19: 1 | BJ19: 1 | BK19: 1 | BL19: 1 | BM19: 1 | BN19: 1 | BO19: 1 | BP19: 1 | BQ19: 1 | BR19: 1 | BS19: 1 | BT19: 3 | BU19: 3 | BV19: 3 | BW19: 3 | BX19: 3 | BY19: 3 | BZ19: 3 | CA19: 3 | CB19: 3 | CC19: 3 | CD19: 3 | CE19: 3 | CF19: 3 | CG19: 3 | CH19: 3 | CI19: 3 | CJ19: 3 | CK19: 3 | CL19: 3 | CM19: 3 | CN19: 3 | CO19: 3 | CP19: 3 | CQ19: 3 | CR19: 5 | CS19: 5 | CT19: 5 | CU19: 5 | CV19: 5 | CW19: 5 | CY19: 9 turn | CZ19: =$CZ$6 -> Chester Wilkinson | DA19: =RANDBETWEEN(0,99) -> 49 | DB19: =RANDBETWEEN(0,99) -> 6 | DC19: =RANDBETWEEN(0,99) -> 88 | DD19: =RANDBETWEEN(0,99) -> 73 | DE19: =RANDBETWEEN(0,99) -> 67 | DF19: =RANDBETWEEN(0,99) -> 2 | DG19: =RANDBETWEEN(0,99) -> 5 | DH19: =RANDBETWEEN(0,99) -> 92 | DI19: =SUMIFS($DS$31:$DS$111,$DR$31:$DR$111,DB$6+DF$6) -> -4 | DJ19: =$DC$6 -> 26 | DP19: 50-59 | DQ19: -5CS | DT19: 11 | DU19: 2 | DV19: Direct Hit
A20: 22 | B20: 0 | C20: 0 | D20: 0 | E20: 0 | F20: 0 | G20: 0 | H20: 0 | I20: 0 | J20: 0 | K20: 0 | L20: 0 | M20: 0 | N20: 0 | O20: 0 | P20: 0 | Q20: 0 | R20: 0 | S20: 0 | T20: 0 | U20: 0 | V20: 0 | W20: 0 | X20: 0 | Y20: 0 | Z20: 0 | AA20: 0 | AB20: 0 | AC20: 0 | AD20: 0 | AE20: 0 | AF20: 0 | AG20: 0 | AH20: 0 | AI20: 0 | AJ20: 0 | AK20: 0 | AL20: 0 | AM20: 0 | AN20: 0 | AO20: 0 | AP20: 1 | AQ20: 1 | AR20: 1 | AS20: 1 | AT20: 1 | AU20: 1 | AV20: 1 | AW20: 1 | AX20: 1 | AY20: 1 | AZ20: 1 | BA20: 1 | BB20: 1 | BC20: 1 | BD20: 1 | BE20: 1 | BF20: 1 | BG20: 1 | BH20: 1 | BI20: 1 | BJ20: 1 | BK20: 1 | BL20: 1 | BM20: 1 | BN20: 1 | BO20: 1 | BP20: 1 | BQ20: 1 | BR20: 1 | BS20: 1 | BT20: 3 | BU20: 3 | BV20: 3 | BW20: 3 | BX20: 3 | BY20: 3 | BZ20: 3 | CA20: 3 | CB20: 3 | CC20: 3 | CD20: 3 | CE20: 3 | CF20: 3 | CG20: 3 | CH20: 3 | CI20: 3 | CJ20: 3 | CK20: 3 | CL20: 3 | CM20: 3 | CN20: 3 | CO20: 3 | CP20: 3 | CQ20: 3 | CR20: 5 | CS20: 5 | CT20: 5 | CU20: 5 | CV20: 5 | CW20: 5 | CY20: 10 turn | CZ20: =$CZ$7 -> Alexander Ashley | DA20: =RANDBETWEEN(0,99) -> 73 | DB20: =RANDBETWEEN(0,99) -> 13 | DC20: =RANDBETWEEN(0,99) -> 99 | DD20: =RANDBETWEEN(0,99) -> 3 | DE20: =RANDBETWEEN(0,99) -> 73 | DF20: =RANDBETWEEN(0,99) -> 70 | DG20: =RANDBETWEEN(0,99) -> 2 | DH20: =RANDBETWEEN(0,99) -> 30 | DI20: =SUMIFS($DS$31:$DS$111,$DR$31:$DR$111,DB$7+DF$7) -> -2 | DJ20: =$DC$7 -> 21 | DP20: 60-69 | DQ20: -6CS | DT20: 12 | DU20: 2 | DV20: Direct Hit
A21: 21 | B21: 0 | C21: 0 | D21: 0 | E21: 0 | F21: 0 | G21: 0 | H21: 0 | I21: 0 | J21: 0 | K21: 0 | L21: 0 | M21: 0 | N21: 0 | O21: 0 | P21: 0 | Q21: 0 | R21: 0 | S21: 0 | T21: 0 | U21: 0 | V21: 0 | W21: 0 | X21: 0 | Y21: 0 | Z21: 0 | AA21: 0 | AB21: 0 | AC21: 0 | AD21: 0 | AE21: 0 | AF21: 0 | AG21: 0 | AH21: 0 | AI21: 0 | AJ21: 0 | AK21: 0 | AL21: 0 | AM21: 0 | AN21: 0 | AO21: 0 | AP21: 1 | AQ21: 1 | AR21: 1 | AS21: 1 | AT21: 1 | AU21: 1 | AV21: 1 | AW21: 1 | AX21: 1 | AY21: 1 | AZ21: 1 | BA21: 1 | BB21: 1 | BC21: 1 | BD21: 1 | BE21: 1 | BF21: 1 | BG21: 1 | BH21: 1 | BI21: 1 | BJ21: 1 | BK21: 1 | BL21: 1 | BM21: 1 | BN21: 1 | BO21: 1 | BP21: 1 | BQ21: 1 | BR21: 1 | BS21: 1 | BT21: 3 | BU21: 3 | BV21: 3 | BW21: 3 | BX21: 3 | BY21: 3 | BZ21: 3 | CA21: 3 | CB21: 3 | CC21: 3 | CD21: 3 | CE21: 3 | CF21: 3 | CG21: 3 | CH21: 3 | CI21: 3 | CJ21: 3 | CK21: 3 | CL21: 3 | CM21: 3 | CN21: 3 | CO21: 3 | CP21: 3 | CQ21: 3 | CR21: 5 | CS21: 5 | CT21: 5 | CU21: 5 | CV21: 5 | CW21: 5 | CY21: 11 turn | CZ21: =$CZ$6 -> Chester Wilkinson | DA21: =RANDBETWEEN(0,99) -> 28 | DB21: =RANDBETWEEN(0,99) -> 79 | DC21: =RANDBETWEEN(0,99) -> 21 | DD21: =RANDBETWEEN(0,99) -> 9 | DE21: =RANDBETWEEN(0,99) -> 0 | DF21: =RANDBETWEEN(0,99) -> 1 | DG21: =RANDBETWEEN(0,99) -> 83 | DH21: =RANDBETWEEN(0,99) -> 18 | DI21: =SUMIFS($DS$31:$DS$111,$DR$31:$DR$111,DB$6+DF$6) -> -4 | DJ21: =$DC$6 -> 26 | DP21: 70-79 | DQ21: -7CS | DT21: 13 | DU21: 2 | DV21: Direct Hit
A22: 20 | B22: 0 | C22: 0 | D22: 0 | E22: 0 | F22: 0 | G22: 0 | H22: 0 | I22: 0 | J22: 0 | K22: 0 | L22: 0 | M22: 0 | N22: 0 | O22: 0 | P22: 0 | Q22: 0 | R22: 0 | S22: 0 | T22: 0 | U22: 0 | V22: 0 | W22: 0 | X22: 0 | Y22: 0 | Z22: 0 | AA22: 0 | AB22: 0 | AC22: 0 | AD22: 0 | AE22: 0 | AF22: 0 | AG22: 0 | AH22: 0 | AI22: 0 | AJ22: 0 | AK22: 0 | AL22: 0 | AM22: 0 | AN22: 0 | AO22: 0 | AP22: 1 | AQ22: 1 | AR22: 1 | AS22: 1 | AT22: 1 | AU22: 1 | AV22: 1 | AW22: 1 | AX22: 1 | AY22: 1 | AZ22: 1 | BA22: 1 | BB22: 1 | BC22: 1 | BD22: 1 | BE22: 1 | BF22: 1 | BG22: 1 | BH22: 1 | BI22: 1 | BJ22: 1 | BK22: 1 | BL22: 1 | BM22: 1 | BN22: 1 | BO22: 1 | BP22: 1 | BQ22: 1 | BR22: 1 | BS22: 1 | BT22: 3 | BU22: 3 | BV22: 3 | BW22: 3 | BX22: 3 | BY22: 3 | BZ22: 3 | CA22: 3 | CB22: 3 | CC22: 3 | CD22: 3 | CE22: 3 | CF22: 3 | CG22: 3 | CH22: 3 | CI22: 3 | CJ22: 3 | CK22: 3 | CL22: 3 | CM22: 3 | CN22: 3 | CO22: 3 | CP22: 3 | CQ22: 3 | CR22: 5 | CS22: 5 | CT22: 5 | CU22: 5 | CV22: 5 | CW22: 5 | CY22: 12 turn | CZ22: =$CZ$7 -> Alexander Ashley | DA22: =RANDBETWEEN(0,99) -> 83 | DB22: =RANDBETWEEN(0,99) -> 80 | DC22: =RANDBETWEEN(0,99) -> 38 | DD22: =RANDBETWEEN(0,99) -> 60 | DE22: =RANDBETWEEN(0,99) -> 16 | DF22: =RANDBETWEEN(0,99) -> 1 | DG22: =RANDBETWEEN(0,99) -> 52 | DH22: =RANDBETWEEN(0,99) -> 75 | DI22: =SUMIFS($DS$31:$DS$111,$DR$31:$DR$111,DB$7+DF$7) -> -2 | DJ22: =$DC$7 -> 21 | DP22: 80-99 | DQ22: -8CS | DT22: 14 | DU22: 2 | DV22: Direct Hit
A23: 19 | B23: 0 | C23: 0 | D23: 0 | E23: 0 | F23: 0 | G23: 0 | H23: 0 | I23: 0 | J23: 0 | K23: 0 | L23: 0 | M23: 0 | N23: 0 | O23: 0 | P23: 0 | Q23: 0 | R23: 0 | S23: 0 | T23: 0 | U23: 0 | V23: 0 | W23: 0 | X23: 0 | Y23: 0 | Z23: 0 | AA23: 0 | AB23: 0 | AC23: 0 | AD23: 0 | AE23: 0 | AF23: 0 | AG23: 0 | AH23: 0 | AI23: 0 | AJ23: 0 | AK23: 0 | AL23: 0 | AM23: 0 | AN23: 0 | AO23: 0 | AP23: 0 | AQ23: 0 | AR23: 0 | AS23: 0 | AT23: 0 | AU23: 1 | AV23: 1 | AW23: 1 | AX23: 1 | AY23: 1 | AZ23: 1 | BA23: 1 | BB23: 1 | BC23: 1 | BD23: 1 | BE23: 1 | BF23: 1 | BG23: 1 | BH23: 1 | BI23: 1 | BJ23: 1 | BK23: 1 | BL23: 1 | BM23: 1 | BN23: 1 | BO23: 1 | BP23: 1 | BQ23: 1 | BR23: 1 | BS23: 1 | BT23: 1 | BU23: 1 | BV23: 1 | BW23: 1 | BX23: 1 | BY23: 3 | BZ23: 3 | CA23: 3 | CB23: 3 | CC23: 3 | CD23: 3 | CE23: 3 | CF23: 3 | CG23: 3 | CH23: 3 | CI23: 3 | CJ23: 3 | CK23: 3 | CL23: 3 | CM23: 3 | CN23: 3 | CO23: 3 | CP23: 3 | CQ23: 3 | CR23: 5 | CS23: 5 | CT23: 5 | CU23: 5 | CV23: 5 | CW23: 5 | CY23: 13 turn | CZ23: =$CZ$6 -> Chester Wilkinson | DA23: =RANDBETWEEN(0,99) -> 39 | DB23: =RANDBETWEEN(0,99) -> 32 | DC23: =RANDBETWEEN(0,99) -> 83 | DD23: =RANDBETWEEN(0,99) -> 62 | DE23: =RANDBETWEEN(0,99) -> 85 | DF23: =RANDBETWEEN(0,99) -> 81 | DG23: =RANDBETWEEN(0,99) -> 90 | DH23: =RANDBETWEEN(0,99) -> 72 | DI23: =SUMIFS($DS$31:$DS$111,$DR$31:$DR$111,DB$6+DF$6) -> -4 | DJ23: =$DC$6 -> 26 | DP23: 100-150 | DQ23: -9CS | DT23: 15 | DU23: 2 | DV23: Direct Hit
A24: 18 | B24: 0 | C24: 0 | D24: 0 | E24: 0 | F24: 0 | G24: 0 | H24: 0 | I24: 0 | J24: 0 | K24: 0 | L24: 0 | M24: 0 | N24: 0 | O24: 0 | P24: 0 | Q24: 0 | R24: 0 | S24: 0 | T24: 0 | U24: 0 | V24: 0 | W24: 0 | X24: 0 | Y24: 0 | Z24: 0 | AA24: 0 | AB24: 0 | AC24: 0 | AD24: 0 | AE24: 0 | AF24: 0 | AG24: 0 | AH24: 0 | AI24: 0 | AJ24: 0 | AK24: 0 | AL24: 0 | AM24: 0 | AN24: 0 | AO24: 0 | AP24: 0 | AQ24: 0 | AR24: 0 | AS24: 0 | AT24: 0 | AU24: 1 | AV24: 1 | AW24: 1 | AX24: 1 | AY24: 1 | AZ24: 1 | BA24: 1 | BB24: 1 | BC24: 1 | BD24: 1 | BE24: 1 | BF24: 1 | BG24: 1 | BH24: 1 | BI24: 1 | BJ24: 1 | BK24: 1 | BL24: 1 | BM24: 1 | BN24: 1 | BO24: 1 | BP24: 1 | BQ24: 1 | BR24: 1 | BS24: 1 | BT24: 1 | BU24: 1 | BV24: 1 | BW24: 1 | BX24: 1 | BY24: 3 | BZ24: 3 | CA24: 3 | CB24: 3 | CC24: 3 | CD24: 3 | CE24: 3 | CF24: 3 | CG24: 3 | CH24: 3 | CI24: 3 | CJ24: 3 | CK24: 3 | CL24: 3 | CM24: 3 | CN24: 3 | CO24: 3 | CP24: 3 | CQ24: 3 | CR24: 5 | CS24: 5 | CT24: 5 | CU24: 5 | CV24: 5 | CW24: 5 | CY24: 14 turn | CZ24: =$CZ$7 -> Alexander Ashley | DA24: =RANDBETWEEN(0,99) -> 50 | DB24: =RANDBETWEEN(0,99) -> 25 | DC24: =RANDBETWEEN(0,99) -> 48 | DD24: =RANDBETWEEN(0,99) -> 85 | DE24: =RANDBETWEEN(0,99) -> 10 | DF24: =RANDBETWEEN(0,99) -> 16 | DG24: =RANDBETWEEN(0,99) -> 78 | DH24: =RANDBETWEEN(0,99) -> 57 | DI24: =SUMIFS($DS$31:$DS$111,$DR$31:$DR$111,DB$7+DF$7) -> -2 | DJ24: =$DC$7 -> 21 | DP24: 150-250 | DQ24: -10CS | DT24: 16 | DU24: 2 | DV24: Direct Hit
A25: 17 | B25: 0 | C25: 0 | D25: 0 | E25: 0 | F25: 0 | G25: 0 | H25: 0 | I25: 0 | J25: 0 | K25: 0 | L25: 0 | M25: 0 | N25: 0 | O25: 0 | P25: 0 | Q25: 0 | R25: 0 | S25: 0 | T25: 0 | U25: 0 | V25: 0 | W25: 0 | X25: 0 | Y25: 0 | Z25: 0 | AA25: 0 | AB25: 0 | AC25: 0 | AD25: 0 | AE25: 0 | AF25: 0 | AG25: 0 | AH25: 0 | AI25: 0 | AJ25: 0 | AK25: 0 | AL25: 0 | AM25: 0 | AN25: 0 | AO25: 0 | AP25: 0 | AQ25: 0 | AR25: 0 | AS25: 0 | AT25: 0 | AU25: 1 | AV25: 1 | AW25: 1 | AX25: 1 | AY25: 1 | AZ25: 1 | BA25: 1 | BB25: 1 | BC25: 1 | BD25: 1 | BE25: 1 | BF25: 1 | BG25: 1 | BH25: 1 | BI25: 1 | BJ25: 1 | BK25: 1 | BL25: 1 | BM25: 1 | BN25: 1 | BO25: 1 | BP25: 1 | BQ25: 1 | BR25: 1 | BS25: 1 | BT25: 1 | BU25: 1 | BV25: 1 | BW25: 1 | BX25: 1 | BY25: 3 | BZ25: 3 | CA25: 3 | CB25: 3 | CC25: 3 | CD25: 3 | CE25: 3 | CF25: 3 | CG25: 3 | CH25: 3 | CI25: 3 | CJ25: 3 | CK25: 3 | CL25: 3 | CM25: 3 | CN25: 3 | CO25: 3 | CP25: 3 | CQ25: 3 | CR25: 5 | CS25: 5 | CT25: 5 | CU25: 5 | CV25: 5 | CW25: 5 | CY25: 15 turn | CZ25: =$CZ$6 -> Chester Wilkinson | DA25: =RANDBETWEEN(0,99) -> 97 | DB25: =RANDBETWEEN(0,99) -> 65 | DC25: =RANDBETWEEN(0,99) -> 21 | DD25: =RANDBETWEEN(0,99) -> 21 | DE25: =RANDBETWEEN(0,99) -> 81 | DF25: =RANDBETWEEN(0,99) -> 50 | DG25: =RANDBETWEEN(0,99) -> 3 | DH25: =RANDBETWEEN(0,99) -> 30 | DI25: =SUMIFS($DS$31:$DS$111,$DR$31:$DR$111,DB$6+DF$6) -> -4 | DJ25: =$DC$6 -> 26 | DP25: 250-500 | DQ25: -11CS | DT25: 17 | DU25: 2 | DV25: Direct Hit
A26: 16 | B26: 0 | C26: 0 | D26: 0 | E26: 0 | F26: 0 | G26: 0 | H26: 0 | I26: 0 | J26: 0 | K26: 0 | L26: 0 | M26: 0 | N26: 0 | O26: 0 | P26: 0 | Q26: 0 | R26: 0 | S26: 0 | T26: 0 | U26: 0 | V26: 0 | W26: 0 | X26: 0 | Y26: 0 | Z26: 0 | AA26: 0 | AB26: 0 | AC26: 0 | AD26: 0 | AE26: 0 | AF26: 0 | AG26: 0 | AH26: 0 | AI26: 0 | AJ26: 0 | AK26: 0 | AL26: 0 | AM26: 0 | AN26: 0 | AO26: 0 | AP26: 0 | AQ26: 0 | AR26: 0 | AS26: 0 | AT26: 0 | AU26: 1 | AV26: 1 | AW26: 1 | AX26: 1 | AY26: 1 | AZ26: 1 | BA26: 1 | BB26: 1 | BC26: 1 | BD26: 1 | BE26: 1 | BF26: 1 | BG26: 1 | BH26: 1 | BI26: 1 | BJ26: 1 | BK26: 1 | BL26: 1 | BM26: 1 | BN26: 1 | BO26: 1 | BP26: 1 | BQ26: 1 | BR26: 1 | BS26: 1 | BT26: 1 | BU26: 1 | BV26: 1 | BW26: 1 | BX26: 1 | BY26: 3 | BZ26: 3 | CA26: 3 | CB26: 3 | CC26: 3 | CD26: 3 | CE26: 3 | CF26: 3 | CG26: 3 | CH26: 3 | CI26: 3 | CJ26: 3 | CK26: 3 | CL26: 3 | CM26: 3 | CN26: 3 | CO26: 3 | CP26: 3 | CQ26: 3 | CR26: 5 | CS26: 5 | CT26: 5 | CU26: 5 | CV26: 5 | CW26: 5 | CY26: 16 turn | CZ26: =$CZ$7 -> Alexander Ashley | DA26: =RANDBETWEEN(0,99) -> 76 | DB26: =RANDBETWEEN(0,99) -> 30 | DC26: =RANDBETWEEN(0,99) -> 28 | DD26: =RANDBETWEEN(0,99) -> 62 | DE26: =RANDBETWEEN(0,99) -> 73 | DF26: =RANDBETWEEN(0,99) -> 42 | DG26: =RANDBETWEEN(0,99) -> 41 | DH26: =RANDBETWEEN(0,99) -> 9 | DI26: =SUMIFS($DS$31:$DS$111,$DR$31:$DR$111,DB$7+DF$7) -> -2 | DJ26: =$DC$7 -> 21 | DP26: 500-999 | DQ26: -12CS | DT26: 18 | DU26: 2 | DV26: Direct Hit
A27: 15 | B27: 0 | C27: 0 | D27: 0 | E27: 0 | F27: 0 | G27: 0 | H27: 0 | I27: 0 | J27: 0 | K27: 0 | L27: 0 | M27: 0 | N27: 0 | O27: 0 | P27: 0 | Q27: 0 | R27: 0 | S27: 0 | T27: 0 | U27: 0 | V27: 0 | W27: 0 | X27: 0 | Y27: 0 | Z27: 0 | AA27: 0 | AB27: 0 | AC27: 0 | AD27: 0 | AE27: 0 | AF27: 0 | AG27: 0 | AH27: 0 | AI27: 0 | AJ27: 0 | AK27: 0 | AL27: 0 | AM27: 0 | AN27: 0 | AO27: 0 | AP27: 0 | AQ27: 0 | AR27: 0 | AS27: 0 | AT27: 0 | AU27: 1 | AV27: 1 | AW27: 1 | AX27: 1 | AY27: 1 | AZ27: 1 | BA27: 1 | BB27: 1 | BC27: 1 | BD27: 1 | BE27: 1 | BF27: 1 | BG27: 1 | BH27: 1 | BI27: 1 | BJ27: 1 | BK27: 1 | BL27: 1 | BM27: 1 | BN27: 1 | BO27: 1 | BP27: 1 | BQ27: 1 | BR27: 1 | BS27: 1 | BT27: 1 | BU27: 1 | BV27: 1 | BW27: 1 | BX27: 1 | BY27: 3 | BZ27: 3 | CA27: 3 | CB27: 3 | CC27: 3 | CD27: 3 | CE27: 3 | CF27: 3 | CG27: 3 | CH27: 3 | CI27: 3 | CJ27: 3 | CK27: 3 | CL27: 3 | CM27: 3 | CN27: 3 | CO27: 3 | CP27: 3 | CQ27: 3 | CR27: 5 | CS27: 5 | CT27: 5 | CU27: 5 | CV27: 5 | CW27: 5 | CY27: 17 turn | CZ27: =$CZ$6 -> Chester Wilkinson | DA27: =RANDBETWEEN(0,99) -> 16 | DB27: =RANDBETWEEN(0,99) -> 46 | DC27: =RANDBETWEEN(0,99) -> 73 | DD27: =RANDBETWEEN(0,99) -> 73 | DE27: =RANDBETWEEN(0,99) -> 59 | DF27: =RANDBETWEEN(0,99) -> 81 | DG27: =RANDBETWEEN(0,99) -> 28 | DH27: =RANDBETWEEN(0,99) -> 28 | DI27: =SUMIFS($DS$31:$DS$111,$DR$31:$DR$111,DB$6+DF$6) -> -4 | DJ27: =$DC$6 -> 26 | DP27: 1000-1499 | DQ27: -13CS | DT27: 19 | DU27: 2 | DV27: Direct Hit
A28: 14 | B28: 0 | C28: 0 | D28: 0 | E28: 0 | F28: 0 | G28: 0 | H28: 0 | I28: 0 | J28: 0 | K28: 0 | L28: 0 | M28: 0 | N28: 0 | O28: 0 | P28: 0 | Q28: 0 | R28: 0 | S28: 0 | T28: 0 | U28: 0 | V28: 0 | W28: 0 | X28: 0 | Y28: 0 | Z28: 0 | AA28: 0 | AB28: 0 | AC28: 0 | AD28: 0 | AE28: 0 | AF28: 0 | AG28: 0 | AH28: 0 | AI28: 0 | AJ28: 0 | AK28: 0 | AL28: 0 | AM28: 0 | AN28: 0 | AO28: 0 | AP28: 0 | AQ28: 0 | AR28: 0 | AS28: 0 | AT28: 0 | AU28: 1 | AV28: 1 | AW28: 1 | AX28: 1 | AY28: 1 | AZ28: 1 | BA28: 1 | BB28: 1 | BC28: 1 | BD28: 1 | BE28: 1 | BF28: 1 | BG28: 1 | BH28: 1 | BI28: 1 | BJ28: 1 | BK28: 1 | BL28: 1 | BM28: 1 | BN28: 1 | BO28: 1 | BP28: 1 | BQ28: 1 | BR28: 1 | BS28: 1 | BT28: 1 | BU28: 1 | BV28: 1 | BW28: 1 | BX28: 1 | BY28: 3 | BZ28: 3 | CA28: 3 | CB28: 3 | CC28: 3 | CD28: 3 | CE28: 3 | CF28: 3 | CG28: 3 | CH28: 3 | CI28: 3 | CJ28: 3 | CK28: 3 | CL28: 3 | CM28: 3 | CN28: 3 | CO28: 3 | CP28: 3 | CQ28: 3 | CR28: 5 | CS28: 5 | CT28: 5 | CU28: 5 | CV28: 5 | CW28: 5 | CY28: 18 turn | CZ28: =$CZ$7 -> Alexander Ashley | DA28: =RANDBETWEEN(0,99) -> 82 | DB28: =RANDBETWEEN(0,99) -> 55 | DC28: =RANDBETWEEN(0,99) -> 15 | DD28: =RANDBETWEEN(0,99) -> 15 | DE28: =RANDBETWEEN(0,99) -> 77 | DF28: =RANDBETWEEN(0,99) -> 24 | DG28: =RANDBETWEEN(0,99) -> 19 | DH28: =RANDBETWEEN(0,99) -> 82 | DI28: =SUMIFS($DS$31:$DS$111,$DR$31:$DR$111,DB$7+DF$7) -> -2 | DJ28: =$DC$7 -> 21 | DP28: 2500-4999 | DQ28: -14CS | DT28: 20 | DU28: 2 | DV28: Direct Hit
A29: 13 | B29: 0 | C29: 0 | D29: 0 | E29: 0 | F29: 0 | G29: 0 | H29: 0 | I29: 0 | J29: 0 | K29: 0 | L29: 0 | M29: 0 | N29: 0 | O29: 0 | P29: 0 | Q29: 0 | R29: 0 | S29: 0 | T29: 0 | U29: 0 | V29: 0 | W29: 0 | X29: 0 | Y29: 0 | Z29: 0 | AA29: 0 | AB29: 0 | AC29: 0 | AD29: 0 | AE29: 0 | AF29: 0 | AG29: 0 | AH29: 0 | AI29: 0 | AJ29: 0 | AK29: 0 | AL29: 0 | AM29: 0 | AN29: 0 | AO29: 0 | AP29: 0 | AQ29: 0 | AR29: 0 | AS29: 0 | AT29: 0 | AU29: 1 | AV29: 1 | AW29: 1 | AX29: 1 | AY29: 1 | AZ29: 1 | BA29: 1 | BB29: 1 | BC29: 1 | BD29: 1 | BE29: 1 | BF29: 1 | BG29: 1 | BH29: 1 | BI29: 1 | BJ29: 1 | BK29: 1 | BL29: 1 | BM29: 1 | BN29: 1 | BO29: 1 | BP29: 1 | BQ29: 1 | BR29: 1 | BS29: 1 | BT29: 1 | BU29: 1 | BV29: 1 | BW29: 1 | BX29: 1 | BY29: 3 | BZ29: 3 | CA29: 3 | CB29: 3 | CC29: 3 | CD29: 3 | CE29: 3 | CF29: 3 | CG29: 3 | CH29: 3 | CI29: 3 | CJ29: 3 | CK29: 3 | CL29: 3 | CM29: 3 | CN29: 3 | CO29: 3 | CP29: 3 | CQ29: 3 | CR29: 5 | CS29: 5 | CT29: 5 | CU29: 5 | CV29: 5 | CW29: 5 | CY29: 19 turn | CZ29: =$CZ$6 -> Chester Wilkinson | DA29: =RANDBETWEEN(0,99) -> 85 | DB29: =RANDBETWEEN(0,99) -> 27 | DC29: =RANDBETWEEN(0,99) -> 40 | DD29: =RANDBETWEEN(0,99) -> 43 | DE29: =RANDBETWEEN(0,99) -> 35 | DF29: =RANDBETWEEN(0,99) -> 68 | DG29: =RANDBETWEEN(0,99) -> 95 | DH29: =RANDBETWEEN(0,99) -> 97 | DI29: =SUMIFS($DS$31:$DS$111,$DR$31:$DR$111,DB$6+DF$6) -> -4 | DJ29: =$DC$6 -> 26 | DT29: 21 | DU29: 2 | DV29: Direct Hit
A30: 12 | B30: 0 | C30: 0 | D30: 0 | E30: 0 | F30: 0 | G30: 0 | H30: 0 | I30: 0 | J30: 0 | K30: 0 | L30: 0 | M30: 0 | N30: 0 | O30: 0 | P30: 0 | Q30: 0 | R30: 0 | S30: 0 | T30: 0 | U30: 0 | V30: 0 | W30: 0 | X30: 0 | Y30: 0 | Z30: 0 | AA30: 0 | AB30: 0 | AC30: 0 | AD30: 0 | AE30: 0 | AF30: 0 | AG30: 0 | AH30: 0 | AI30: 0 | AJ30: 0 | AK30: 0 | AL30: 0 | AM30: 0 | AN30: 0 | AO30: 0 | AP30: 0 | AQ30: 0 | AR30: 0 | AS30: 0 | AT30: 0 | AU30: 1 | AV30: 1 | AW30: 1 | AX30: 1 | AY30: 1 | AZ30: 1 | BA30: 1 | BB30: 1 | BC30: 1 | BD30: 1 | BE30: 1 | BF30: 1 | BG30: 1 | BH30: 1 | BI30: 1 | BJ30: 1 | BK30: 1 | BL30: 1 | BM30: 1 | BN30: 1 | BO30: 1 | BP30: 1 | BQ30: 1 | BR30: 1 | BS30: 1 | BT30: 1 | BU30: 1 | BV30: 1 | BW30: 1 | BX30: 1 | BY30: 3 | BZ30: 3 | CA30: 3 | CB30: 3 | CC30: 3 | CD30: 3 | CE30: 3 | CF30: 3 | CG30: 3 | CH30: 3 | CI30: 3 | CJ30: 3 | CK30: 3 | CL30: 3 | CM30: 3 | CN30: 3 | CO30: 3 | CP30: 3 | CQ30: 3 | CR30: 5 | CS30: 5 | CT30: 5 | CU30: 5 | CV30: 5 | CW30: 5 | CY30: 20 turn | CZ30: =$CZ$7 -> Alexander Ashley | DA30: =RANDBETWEEN(0,99) -> 21 | DB30: =RANDBETWEEN(0,99) -> 89 | DC30: =RANDBETWEEN(0,99) -> 32 | DD30: =RANDBETWEEN(0,99) -> 68 | DE30: =RANDBETWEEN(0,99) -> 97 | DF30: =RANDBETWEEN(0,99) -> 57 | DG30: =RANDBETWEEN(0,99) -> 11 | DH30: =RANDBETWEEN(0,99) -> 21 | DI30: =SUMIFS($DS$31:$DS$111,$DR$31:$DR$111,DB$7+DF$7) -> -2 | DJ30: =$DC$7 -> 21 | DP30: Agility | DQ30: Instinct | DR30: Sum A+I | DS30: -CS | DT30: 22 | DU30: 2 | DV30: Direct Hit
A31: 11 | B31: 0 | C31: 0 | D31: 0 | E31: 0 | F31: 0 | G31: 0 | H31: 0 | I31: 0 | J31: 0 | K31: 0 | L31: 0 | M31: 0 | N31: 0 | O31: 0 | P31: 0 | Q31: 0 | R31: 0 | S31: 0 | T31: 0 | U31: 0 | V31: 0 | W31: 0 | X31: 0 | Y31: 0 | Z31: 0 | AA31: 0 | AB31: 0 | AC31: 0 | AD31: 0 | AE31: 0 | AF31: 0 | AG31: 0 | AH31: 0 | AI31: 0 | AJ31: 0 | AK31: 0 | AL31: 0 | AM31: 0 | AN31: 0 | AO31: 0 | AP31: 0 | AQ31: 0 | AR31: 0 | AS31: 0 | AT31: 0 | AU31: 1 | AV31: 1 | AW31: 1 | AX31: 1 | AY31: 1 | AZ31: 1 | BA31: 1 | BB31: 1 | BC31: 1 | BD31: 1 | BE31: 1 | BF31: 1 | BG31: 1 | BH31: 1 | BI31: 1 | BJ31: 1 | BK31: 1 | BL31: 1 | BM31: 1 | BN31: 1 | BO31: 1 | BP31: 1 | BQ31: 1 | BR31: 1 | BS31: 1 | BT31: 1 | BU31: 1 | BV31: 1 | BW31: 1 | BX31: 1 | BY31: 3 | BZ31: 3 | CA31: 3 | CB31: 3 | CC31: 3 | CD31: 3 | CE31: 3 | CF31: 3 | CG31: 3 | CH31: 3 | CI31: 3 | CJ31: 3 | CK31: 3 | CL31: 3 | CM31: 3 | CN31: 3 | CO31: 3 | CP31: 3 | CQ31: 3 | CR31: 5 | CS31: 5 | CT31: 5 | CU31: 5 | CV31: 5 | CW31: 5 | CY31: 21 turn | CZ31: =$CZ$6 -> Chester Wilkinson | DA31: =RANDBETWEEN(0,99) -> 48 | DB31: =RANDBETWEEN(0,99) -> 79 | DC31: =RANDBETWEEN(0,99) -> 77 | DD31: =RANDBETWEEN(0,99) -> 36 | DE31: =RANDBETWEEN(0,99) -> 1 | DF31: =RANDBETWEEN(0,99) -> 89 | DG31: =RANDBETWEEN(0,99) -> 11 | DH31: =RANDBETWEEN(0,99) -> 21 | DI31: =SUMIFS($DS$31:$DS$111,$DR$31:$DR$111,DB$6+DF$6) -> -4 | DJ31: =$DC$6 -> 26 | DP31: 0 | DQ31: 0 | DR31: 0 | DS31: -1 | DT31: 23 | DU31: 2 | DV31: Direct Hit
